[2025-01-31T18:15:51.181+0000] {taskinstance.py:1159} INFO - Dependencies all met for dep_context=non-requeueable deps ti=<TaskInstance: dag_d_pipeline_compass_reviews.group_ingestion.group_jobs_mongo.MONGO_INGESTION_SANTANDER-WAY manual__2025-01-31T18:15:10.850711+00:00 [queued]>
[2025-01-31T18:15:51.190+0000] {taskinstance.py:1159} INFO - Dependencies all met for dep_context=requeueable deps ti=<TaskInstance: dag_d_pipeline_compass_reviews.group_ingestion.group_jobs_mongo.MONGO_INGESTION_SANTANDER-WAY manual__2025-01-31T18:15:10.850711+00:00 [queued]>
[2025-01-31T18:15:51.190+0000] {taskinstance.py:1361} INFO - Starting attempt 2 of 3
[2025-01-31T18:15:51.200+0000] {taskinstance.py:1382} INFO - Executing <Task(PythonOperator): group_ingestion.group_jobs_mongo.MONGO_INGESTION_SANTANDER-WAY> on 2025-01-31 18:15:10.850711+00:00
[2025-01-31T18:15:51.203+0000] {standard_task_runner.py:57} INFO - Started process 128 to run task
[2025-01-31T18:15:51.206+0000] {standard_task_runner.py:84} INFO - Running: ['***', 'tasks', 'run', 'dag_d_pipeline_compass_reviews', 'group_ingestion.group_jobs_mongo.MONGO_INGESTION_SANTANDER-WAY', 'manual__2025-01-31T18:15:10.850711+00:00', '--job-id', '556', '--raw', '--subdir', 'DAGS_FOLDER/dag_d_pipeline_compass_reviews.py', '--cfg-path', '/tmp/tmpcu2_3wxu']
[2025-01-31T18:15:51.207+0000] {standard_task_runner.py:85} INFO - Job 556: Subtask group_ingestion.group_jobs_mongo.MONGO_INGESTION_SANTANDER-WAY
[2025-01-31T18:15:51.245+0000] {task_command.py:416} INFO - Running <TaskInstance: dag_d_pipeline_compass_reviews.group_ingestion.group_jobs_mongo.MONGO_INGESTION_SANTANDER-WAY manual__2025-01-31T18:15:10.850711+00:00 [running]> on host 0b9ec68f410c
[2025-01-31T18:15:51.322+0000] {taskinstance.py:1662} INFO - Exporting env vars: AIRFLOW_CTX_DAG_EMAIL='gacarvalho.contato@gmail.com' AIRFLOW_CTX_DAG_OWNER='gacarvalho' AIRFLOW_CTX_DAG_ID='dag_d_pipeline_compass_reviews' AIRFLOW_CTX_TASK_ID='group_ingestion.group_jobs_mongo.MONGO_INGESTION_SANTANDER-WAY' AIRFLOW_CTX_EXECUTION_DATE='2025-01-31T18:15:10.850711+00:00' AIRFLOW_CTX_TRY_NUMBER='2' AIRFLOW_CTX_DAG_RUN_ID='manual__2025-01-31T18:15:10.850711+00:00'
[2025-01-31T18:19:14.361+0000] {logging_mixin.py:151} INFO - Erro ao executar Docker Run: Command '['docker', 'run', '--rm', '--network', 'hadoop_network', '-e', 'CONFIG_ENV=prod', '-e', 'PARAM1=santander-way', '-e', 'PARAM2=sim', '-v', '/env/.env:/app/.env', '-v', '/opt/***/data:/app/data', 'iamgacarvalho/dmc-app-ingestion-reviews-mongodb-hdfs-compass:1.0.0']' returned non-zero exit status 1.
[2025-01-31T18:19:14.362+0000] {taskinstance.py:1937} ERROR - Task failed with exception
Traceback (most recent call last):
  File "/home/airflow/.local/lib/python3.8/site-packages/airflow/operators/python.py", line 192, in execute
    return_value = self.execute_callable()
  File "/home/airflow/.local/lib/python3.8/site-packages/airflow/operators/python.py", line 209, in execute_callable
    return self.python_callable(*self.op_args, **self.op_kwargs)
  File "/opt/airflow/dags/dag_d_pipeline_compass_reviews.py", line 41, in run_docker_run
    subprocess.run(command, check=True, env=os.environ.copy())
  File "/usr/local/lib/python3.8/subprocess.py", line 516, in run
    raise CalledProcessError(retcode, process.args,
subprocess.CalledProcessError: Command '['docker', 'run', '--rm', '--network', 'hadoop_network', '-e', 'CONFIG_ENV=prod', '-e', 'PARAM1=santander-way', '-e', 'PARAM2=sim', '-v', '/env/.env:/app/.env', '-v', '/opt/airflow/data:/app/data', 'iamgacarvalho/dmc-app-ingestion-reviews-mongodb-hdfs-compass:1.0.0']' returned non-zero exit status 1.
[2025-01-31T18:19:14.371+0000] {taskinstance.py:1400} INFO - Marking task as UP_FOR_RETRY. dag_id=dag_d_pipeline_compass_reviews, task_id=group_ingestion.group_jobs_mongo.MONGO_INGESTION_SANTANDER-WAY, execution_date=20250131T181510, start_date=20250131T181551, end_date=20250131T181914
[2025-01-31T18:19:14.386+0000] {warnings.py:109} WARNING - /home/***/.local/lib/python3.8/site-packages/***/utils/email.py:154: RemovedInAirflow3Warning: Fetching SMTP credentials from configuration variables will be deprecated in a future release. Please set credentials using a connection instead.
  send_mime_email(e_from=mail_from, e_to=recipients, mime_msg=msg, conn_id=conn_id, dryrun=dryrun)

[2025-01-31T18:19:14.386+0000] {configuration.py:1068} WARNING - section/key [smtp/smtp_user] not found in config
[2025-01-31T18:19:14.386+0000] {email.py:270} INFO - Email alerting: attempt 1
[2025-01-31T18:19:14.392+0000] {configuration.py:1068} WARNING - section/key [smtp/smtp_user] not found in config
[2025-01-31T18:19:14.392+0000] {email.py:270} INFO - Email alerting: attempt 1
[2025-01-31T18:19:14.392+0000] {taskinstance.py:2007} ERROR - Failed to send email to: ['gacarvalho.contato@gmail.com']
Traceback (most recent call last):
  File "/home/airflow/.local/lib/python3.8/site-packages/airflow/models/taskinstance.py", line 1518, in _run_raw_task
    self._execute_task_with_callbacks(context, test_mode, session=session)
  File "/home/airflow/.local/lib/python3.8/site-packages/airflow/models/taskinstance.py", line 1681, in _execute_task_with_callbacks
    result = self._execute_task(context, task_orig)
  File "/home/airflow/.local/lib/python3.8/site-packages/airflow/models/taskinstance.py", line 1744, in _execute_task
    result = execute_callable(context=context, **execute_callable_kwargs)
  File "/home/airflow/.local/lib/python3.8/site-packages/airflow/operators/python.py", line 192, in execute
    return_value = self.execute_callable()
  File "/home/airflow/.local/lib/python3.8/site-packages/airflow/operators/python.py", line 209, in execute_callable
    return self.python_callable(*self.op_args, **self.op_kwargs)
  File "/opt/airflow/dags/dag_d_pipeline_compass_reviews.py", line 41, in run_docker_run
    subprocess.run(command, check=True, env=os.environ.copy())
  File "/usr/local/lib/python3.8/subprocess.py", line 516, in run
    raise CalledProcessError(retcode, process.args,
subprocess.CalledProcessError: Command '['docker', 'run', '--rm', '--network', 'hadoop_network', '-e', 'CONFIG_ENV=prod', '-e', 'PARAM1=santander-way', '-e', 'PARAM2=sim', '-v', '/env/.env:/app/.env', '-v', '/opt/airflow/data:/app/data', 'iamgacarvalho/dmc-app-ingestion-reviews-mongodb-hdfs-compass:1.0.0']' returned non-zero exit status 1.

During handling of the above exception, another exception occurred:

Traceback (most recent call last):
  File "/home/airflow/.local/lib/python3.8/site-packages/airflow/models/taskinstance.py", line 2420, in email_alert
    send_email(task.email, subject, html_content)
  File "/home/airflow/.local/lib/python3.8/site-packages/airflow/utils/email.py", line 80, in send_email
    return backend(
  File "/home/airflow/.local/lib/python3.8/site-packages/airflow/utils/email.py", line 154, in send_email_smtp
    send_mime_email(e_from=mail_from, e_to=recipients, mime_msg=msg, conn_id=conn_id, dryrun=dryrun)
  File "/home/airflow/.local/lib/python3.8/site-packages/airflow/utils/email.py", line 272, in send_mime_email
    smtp_conn = _get_smtp_connection(smtp_host, smtp_port, smtp_timeout, smtp_ssl)
  File "/home/airflow/.local/lib/python3.8/site-packages/airflow/utils/email.py", line 316, in _get_smtp_connection
    return smtplib.SMTP(host=host, port=port, timeout=timeout)
  File "/usr/local/lib/python3.8/smtplib.py", line 255, in __init__
    (code, msg) = self.connect(host, port)
  File "/usr/local/lib/python3.8/smtplib.py", line 339, in connect
    self.sock = self._get_socket(host, port, self.timeout)
  File "/usr/local/lib/python3.8/smtplib.py", line 310, in _get_socket
    return socket.create_connection((host, port), timeout,
  File "/usr/local/lib/python3.8/socket.py", line 808, in create_connection
    raise err
  File "/usr/local/lib/python3.8/socket.py", line 796, in create_connection
    sock.connect(sa)
ConnectionRefusedError: [Errno 111] Connection refused

During handling of the above exception, another exception occurred:

Traceback (most recent call last):
  File "/home/airflow/.local/lib/python3.8/site-packages/airflow/models/taskinstance.py", line 2005, in handle_failure
    self.email_alert(error, task)
  File "/home/airflow/.local/lib/python3.8/site-packages/airflow/models/taskinstance.py", line 2422, in email_alert
    send_email(task.email, subject, html_content_err)
  File "/home/airflow/.local/lib/python3.8/site-packages/airflow/utils/email.py", line 80, in send_email
    return backend(
  File "/home/airflow/.local/lib/python3.8/site-packages/airflow/utils/email.py", line 154, in send_email_smtp
    send_mime_email(e_from=mail_from, e_to=recipients, mime_msg=msg, conn_id=conn_id, dryrun=dryrun)
  File "/home/airflow/.local/lib/python3.8/site-packages/airflow/utils/email.py", line 272, in send_mime_email
    smtp_conn = _get_smtp_connection(smtp_host, smtp_port, smtp_timeout, smtp_ssl)
  File "/home/airflow/.local/lib/python3.8/site-packages/airflow/utils/email.py", line 316, in _get_smtp_connection
    return smtplib.SMTP(host=host, port=port, timeout=timeout)
  File "/usr/local/lib/python3.8/smtplib.py", line 255, in __init__
    (code, msg) = self.connect(host, port)
  File "/usr/local/lib/python3.8/smtplib.py", line 339, in connect
    self.sock = self._get_socket(host, port, self.timeout)
  File "/usr/local/lib/python3.8/smtplib.py", line 310, in _get_socket
    return socket.create_connection((host, port), timeout,
  File "/usr/local/lib/python3.8/socket.py", line 808, in create_connection
    raise err
  File "/usr/local/lib/python3.8/socket.py", line 796, in create_connection
    sock.connect(sa)
ConnectionRefusedError: [Errno 111] Connection refused
[2025-01-31T18:19:14.410+0000] {standard_task_runner.py:104} ERROR - Failed to execute job 556 for task group_ingestion.group_jobs_mongo.MONGO_INGESTION_SANTANDER-WAY (Command '['docker', 'run', '--rm', '--network', 'hadoop_network', '-e', 'CONFIG_ENV=prod', '-e', 'PARAM1=santander-way', '-e', 'PARAM2=sim', '-v', '/env/.env:/app/.env', '-v', '/opt/airflow/data:/app/data', 'iamgacarvalho/dmc-app-ingestion-reviews-mongodb-hdfs-compass:1.0.0']' returned non-zero exit status 1.; 128)
[2025-01-31T18:19:14.447+0000] {local_task_job_runner.py:228} INFO - Task exited with return code 1
[2025-01-31T18:19:14.473+0000] {taskinstance.py:2778} INFO - 0 downstream tasks scheduled from follow-on schedule check
