[2025-01-28T00:07:29.391+0000] {processor.py:157} INFO - Started process (PID=31) to work on /opt/airflow/dags/dag_d_pipeline_compass_reviews.py
[2025-01-28T00:07:29.393+0000] {processor.py:829} INFO - Processing file /opt/airflow/dags/dag_d_pipeline_compass_reviews.py for tasks to queue
[2025-01-28T00:07:29.404+0000] {logging_mixin.py:151} INFO - [2025-01-28T00:07:29.404+0000] {dagbag.py:536} INFO - Filling up the DagBag from /opt/airflow/dags/dag_d_pipeline_compass_reviews.py
[2025-01-28T00:07:29.438+0000] {logging_mixin.py:151} WARNING - /home/airflow/.local/lib/python3.8/site-packages/airflow/operators/python.py:177 RemovedInAirflow3Warning: The 'task_concurrency' parameter is deprecated. Please use 'max_active_tis_per_dag'.
[2025-01-28T00:07:29.474+0000] {processor.py:839} INFO - DAG(s) dict_keys(['dag_d_pipeline_compass_reviews']) retrieved from /opt/airflow/dags/dag_d_pipeline_compass_reviews.py
[2025-01-28T00:07:29.560+0000] {logging_mixin.py:151} INFO - [2025-01-28T00:07:29.560+0000] {dag.py:2941} INFO - Sync 1 DAGs
[2025-01-28T00:07:29.614+0000] {logging_mixin.py:151} INFO - [2025-01-28T00:07:29.614+0000] {dag.py:3722} INFO - Setting next_dagrun for dag_d_pipeline_compass_reviews to 2025-01-27T06:00:00+00:00, run_after=2025-01-28T06:00:00+00:00
[2025-01-28T00:07:30.306+0000] {processor.py:179} INFO - Processing /opt/airflow/dags/dag_d_pipeline_compass_reviews.py took 0.942 seconds
[2025-01-28T00:07:38.467+0000] {processor.py:157} INFO - Started process (PID=32) to work on /opt/airflow/dags/dag_d_pipeline_compass_reviews.py
[2025-01-28T00:07:38.470+0000] {processor.py:829} INFO - Processing file /opt/airflow/dags/dag_d_pipeline_compass_reviews.py for tasks to queue
[2025-01-28T00:07:38.472+0000] {logging_mixin.py:151} INFO - [2025-01-28T00:07:38.471+0000] {dagbag.py:536} INFO - Filling up the DagBag from /opt/airflow/dags/dag_d_pipeline_compass_reviews.py
[2025-01-28T00:07:38.483+0000] {logging_mixin.py:151} WARNING - /home/airflow/.local/lib/python3.8/site-packages/airflow/operators/python.py:177 RemovedInAirflow3Warning: The 'task_concurrency' parameter is deprecated. Please use 'max_active_tis_per_dag'.
[2025-01-28T00:07:38.497+0000] {processor.py:839} INFO - DAG(s) dict_keys(['dag_d_pipeline_compass_reviews']) retrieved from /opt/airflow/dags/dag_d_pipeline_compass_reviews.py
[2025-01-28T00:07:38.526+0000] {logging_mixin.py:151} INFO - [2025-01-28T00:07:38.525+0000] {taskinstance.py:1939} ERROR - {'DAG Id': 'dag_d_pipeline_compass_reviews', 'Task Id': 'group_jobs_silver.SILVER_APP_SILVER_MONGODB', 'Run Id': 'manual__2025-01-27T23:17:23.147544+00:00', 'Hostname': 'd105ef38d638', 'External Executor Id': '3e129265-18b5-48de-9f09-ab167a2a98aa'}
[2025-01-28T00:07:38.543+0000] {logging_mixin.py:151} INFO - [2025-01-28T00:07:38.543+0000] {taskinstance.py:1400} INFO - Marking task as UP_FOR_RETRY. dag_id=dag_d_pipeline_compass_reviews, task_id=group_jobs_silver.SILVER_APP_SILVER_MONGODB, execution_date=20250127T231723, start_date=20250127T232846, end_date=20250128T000738
[2025-01-28T00:07:38.580+0000] {logging_mixin.py:151} WARNING - /home/airflow/.local/lib/python3.8/site-packages/airflow/utils/email.py:154 RemovedInAirflow3Warning: Fetching SMTP credentials from configuration variables will be deprecated in a future release. Please set credentials using a connection instead.
[2025-01-28T00:07:38.580+0000] {logging_mixin.py:151} INFO - [2025-01-28T00:07:38.580+0000] {configuration.py:1068} WARNING - section/key [smtp/smtp_user] not found in config
[2025-01-28T00:07:38.581+0000] {logging_mixin.py:151} INFO - [2025-01-28T00:07:38.581+0000] {email.py:270} INFO - Email alerting: attempt 1
[2025-01-28T00:07:38.586+0000] {logging_mixin.py:151} INFO - [2025-01-28T00:07:38.586+0000] {configuration.py:1068} WARNING - section/key [smtp/smtp_user] not found in config
[2025-01-28T00:07:38.586+0000] {logging_mixin.py:151} INFO - [2025-01-28T00:07:38.586+0000] {email.py:270} INFO - Email alerting: attempt 1
[2025-01-28T00:07:38.588+0000] {logging_mixin.py:151} INFO - [2025-01-28T00:07:38.586+0000] {taskinstance.py:2007} ERROR - Failed to send email to: ['gacarvalho.contato@gmail.com']
Traceback (most recent call last):
  File "/home/airflow/.local/lib/python3.8/site-packages/airflow/models/taskinstance.py", line 2420, in email_alert
    send_email(task.email, subject, html_content)
  File "/home/airflow/.local/lib/python3.8/site-packages/airflow/utils/email.py", line 80, in send_email
    return backend(
  File "/home/airflow/.local/lib/python3.8/site-packages/airflow/utils/email.py", line 154, in send_email_smtp
    send_mime_email(e_from=mail_from, e_to=recipients, mime_msg=msg, conn_id=conn_id, dryrun=dryrun)
  File "/home/airflow/.local/lib/python3.8/site-packages/airflow/utils/email.py", line 272, in send_mime_email
    smtp_conn = _get_smtp_connection(smtp_host, smtp_port, smtp_timeout, smtp_ssl)
  File "/home/airflow/.local/lib/python3.8/site-packages/airflow/utils/email.py", line 316, in _get_smtp_connection
    return smtplib.SMTP(host=host, port=port, timeout=timeout)
  File "/usr/local/lib/python3.8/smtplib.py", line 255, in __init__
    (code, msg) = self.connect(host, port)
  File "/usr/local/lib/python3.8/smtplib.py", line 339, in connect
    self.sock = self._get_socket(host, port, self.timeout)
  File "/usr/local/lib/python3.8/smtplib.py", line 310, in _get_socket
    return socket.create_connection((host, port), timeout,
  File "/usr/local/lib/python3.8/socket.py", line 808, in create_connection
    raise err
  File "/usr/local/lib/python3.8/socket.py", line 796, in create_connection
    sock.connect(sa)
ConnectionRefusedError: [Errno 111] Connection refused

During handling of the above exception, another exception occurred:

Traceback (most recent call last):
  File "/home/airflow/.local/lib/python3.8/site-packages/airflow/models/taskinstance.py", line 2005, in handle_failure
    self.email_alert(error, task)
  File "/home/airflow/.local/lib/python3.8/site-packages/airflow/models/taskinstance.py", line 2422, in email_alert
    send_email(task.email, subject, html_content_err)
  File "/home/airflow/.local/lib/python3.8/site-packages/airflow/utils/email.py", line 80, in send_email
    return backend(
  File "/home/airflow/.local/lib/python3.8/site-packages/airflow/utils/email.py", line 154, in send_email_smtp
    send_mime_email(e_from=mail_from, e_to=recipients, mime_msg=msg, conn_id=conn_id, dryrun=dryrun)
  File "/home/airflow/.local/lib/python3.8/site-packages/airflow/utils/email.py", line 272, in send_mime_email
    smtp_conn = _get_smtp_connection(smtp_host, smtp_port, smtp_timeout, smtp_ssl)
  File "/home/airflow/.local/lib/python3.8/site-packages/airflow/utils/email.py", line 316, in _get_smtp_connection
    return smtplib.SMTP(host=host, port=port, timeout=timeout)
  File "/usr/local/lib/python3.8/smtplib.py", line 255, in __init__
    (code, msg) = self.connect(host, port)
  File "/usr/local/lib/python3.8/smtplib.py", line 339, in connect
    self.sock = self._get_socket(host, port, self.timeout)
  File "/usr/local/lib/python3.8/smtplib.py", line 310, in _get_socket
    return socket.create_connection((host, port), timeout,
  File "/usr/local/lib/python3.8/socket.py", line 808, in create_connection
    raise err
  File "/usr/local/lib/python3.8/socket.py", line 796, in create_connection
    sock.connect(sa)
ConnectionRefusedError: [Errno 111] Connection refused
[2025-01-28T00:07:38.608+0000] {processor.py:790} INFO - Executed failure callback for <TaskInstance: dag_d_pipeline_compass_reviews.group_jobs_silver.SILVER_APP_SILVER_MONGODB manual__2025-01-27T23:17:23.147544+00:00 [up_for_retry]> in state up_for_retry
[2025-01-28T00:07:38.643+0000] {logging_mixin.py:151} INFO - [2025-01-28T00:07:38.643+0000] {dag.py:2941} INFO - Sync 1 DAGs
[2025-01-28T00:07:38.666+0000] {logging_mixin.py:151} INFO - [2025-01-28T00:07:38.666+0000] {dag.py:3722} INFO - Setting next_dagrun for dag_d_pipeline_compass_reviews to 2025-01-27T06:00:00+00:00, run_after=2025-01-28T06:00:00+00:00
[2025-01-28T00:07:38.686+0000] {processor.py:179} INFO - Processing /opt/airflow/dags/dag_d_pipeline_compass_reviews.py took 0.223 seconds
[2025-01-28T00:07:48.545+0000] {processor.py:157} INFO - Started process (PID=33) to work on /opt/airflow/dags/dag_d_pipeline_compass_reviews.py
[2025-01-28T00:07:48.546+0000] {processor.py:829} INFO - Processing file /opt/airflow/dags/dag_d_pipeline_compass_reviews.py for tasks to queue
[2025-01-28T00:07:48.548+0000] {logging_mixin.py:151} INFO - [2025-01-28T00:07:48.548+0000] {dagbag.py:536} INFO - Filling up the DagBag from /opt/airflow/dags/dag_d_pipeline_compass_reviews.py
[2025-01-28T00:07:48.559+0000] {logging_mixin.py:151} WARNING - /home/airflow/.local/lib/python3.8/site-packages/airflow/operators/python.py:177 RemovedInAirflow3Warning: The 'task_concurrency' parameter is deprecated. Please use 'max_active_tis_per_dag'.
[2025-01-28T00:07:48.565+0000] {processor.py:839} INFO - DAG(s) dict_keys(['dag_d_pipeline_compass_reviews']) retrieved from /opt/airflow/dags/dag_d_pipeline_compass_reviews.py
[2025-01-28T00:07:48.586+0000] {logging_mixin.py:151} INFO - [2025-01-28T00:07:48.586+0000] {taskinstance.py:1939} ERROR - {'DAG Id': 'dag_d_pipeline_compass_reviews', 'Task Id': 'group_jobs_silver.SILVER_APP_SILVER_GOOGLE_PLAY', 'Run Id': 'manual__2025-01-27T23:17:23.147544+00:00', 'Hostname': 'd105ef38d638', 'External Executor Id': '7039e3b4-34cc-48a7-a70f-c83fb6bec985'}
[2025-01-28T00:07:48.604+0000] {logging_mixin.py:151} INFO - [2025-01-28T00:07:48.604+0000] {taskinstance.py:1400} INFO - Marking task as UP_FOR_RETRY. dag_id=dag_d_pipeline_compass_reviews, task_id=group_jobs_silver.SILVER_APP_SILVER_GOOGLE_PLAY, execution_date=20250127T231723, start_date=20250127T232714, end_date=20250128T000748
[2025-01-28T00:07:48.619+0000] {logging_mixin.py:151} WARNING - /home/airflow/.local/lib/python3.8/site-packages/airflow/utils/email.py:154 RemovedInAirflow3Warning: Fetching SMTP credentials from configuration variables will be deprecated in a future release. Please set credentials using a connection instead.
[2025-01-28T00:07:48.620+0000] {logging_mixin.py:151} INFO - [2025-01-28T00:07:48.620+0000] {configuration.py:1068} WARNING - section/key [smtp/smtp_user] not found in config
[2025-01-28T00:07:48.620+0000] {logging_mixin.py:151} INFO - [2025-01-28T00:07:48.620+0000] {email.py:270} INFO - Email alerting: attempt 1
[2025-01-28T00:07:48.622+0000] {logging_mixin.py:151} INFO - [2025-01-28T00:07:48.622+0000] {configuration.py:1068} WARNING - section/key [smtp/smtp_user] not found in config
[2025-01-28T00:07:48.622+0000] {logging_mixin.py:151} INFO - [2025-01-28T00:07:48.622+0000] {email.py:270} INFO - Email alerting: attempt 1
[2025-01-28T00:07:48.624+0000] {logging_mixin.py:151} INFO - [2025-01-28T00:07:48.623+0000] {taskinstance.py:2007} ERROR - Failed to send email to: ['gacarvalho.contato@gmail.com']
Traceback (most recent call last):
  File "/home/airflow/.local/lib/python3.8/site-packages/airflow/models/taskinstance.py", line 2420, in email_alert
    send_email(task.email, subject, html_content)
  File "/home/airflow/.local/lib/python3.8/site-packages/airflow/utils/email.py", line 80, in send_email
    return backend(
  File "/home/airflow/.local/lib/python3.8/site-packages/airflow/utils/email.py", line 154, in send_email_smtp
    send_mime_email(e_from=mail_from, e_to=recipients, mime_msg=msg, conn_id=conn_id, dryrun=dryrun)
  File "/home/airflow/.local/lib/python3.8/site-packages/airflow/utils/email.py", line 272, in send_mime_email
    smtp_conn = _get_smtp_connection(smtp_host, smtp_port, smtp_timeout, smtp_ssl)
  File "/home/airflow/.local/lib/python3.8/site-packages/airflow/utils/email.py", line 316, in _get_smtp_connection
    return smtplib.SMTP(host=host, port=port, timeout=timeout)
  File "/usr/local/lib/python3.8/smtplib.py", line 255, in __init__
    (code, msg) = self.connect(host, port)
  File "/usr/local/lib/python3.8/smtplib.py", line 339, in connect
    self.sock = self._get_socket(host, port, self.timeout)
  File "/usr/local/lib/python3.8/smtplib.py", line 310, in _get_socket
    return socket.create_connection((host, port), timeout,
  File "/usr/local/lib/python3.8/socket.py", line 808, in create_connection
    raise err
  File "/usr/local/lib/python3.8/socket.py", line 796, in create_connection
    sock.connect(sa)
ConnectionRefusedError: [Errno 111] Connection refused

During handling of the above exception, another exception occurred:

Traceback (most recent call last):
  File "/home/airflow/.local/lib/python3.8/site-packages/airflow/models/taskinstance.py", line 2005, in handle_failure
    self.email_alert(error, task)
  File "/home/airflow/.local/lib/python3.8/site-packages/airflow/models/taskinstance.py", line 2422, in email_alert
    send_email(task.email, subject, html_content_err)
  File "/home/airflow/.local/lib/python3.8/site-packages/airflow/utils/email.py", line 80, in send_email
    return backend(
  File "/home/airflow/.local/lib/python3.8/site-packages/airflow/utils/email.py", line 154, in send_email_smtp
    send_mime_email(e_from=mail_from, e_to=recipients, mime_msg=msg, conn_id=conn_id, dryrun=dryrun)
  File "/home/airflow/.local/lib/python3.8/site-packages/airflow/utils/email.py", line 272, in send_mime_email
    smtp_conn = _get_smtp_connection(smtp_host, smtp_port, smtp_timeout, smtp_ssl)
  File "/home/airflow/.local/lib/python3.8/site-packages/airflow/utils/email.py", line 316, in _get_smtp_connection
    return smtplib.SMTP(host=host, port=port, timeout=timeout)
  File "/usr/local/lib/python3.8/smtplib.py", line 255, in __init__
    (code, msg) = self.connect(host, port)
  File "/usr/local/lib/python3.8/smtplib.py", line 339, in connect
    self.sock = self._get_socket(host, port, self.timeout)
  File "/usr/local/lib/python3.8/smtplib.py", line 310, in _get_socket
    return socket.create_connection((host, port), timeout,
  File "/usr/local/lib/python3.8/socket.py", line 808, in create_connection
    raise err
  File "/usr/local/lib/python3.8/socket.py", line 796, in create_connection
    sock.connect(sa)
ConnectionRefusedError: [Errno 111] Connection refused
[2025-01-28T00:07:48.632+0000] {processor.py:790} INFO - Executed failure callback for <TaskInstance: dag_d_pipeline_compass_reviews.group_jobs_silver.SILVER_APP_SILVER_GOOGLE_PLAY manual__2025-01-27T23:17:23.147544+00:00 [up_for_retry]> in state up_for_retry
[2025-01-28T00:07:48.634+0000] {logging_mixin.py:151} INFO - [2025-01-28T00:07:48.634+0000] {taskinstance.py:1939} ERROR - {'DAG Id': 'dag_d_pipeline_compass_reviews', 'Task Id': 'group_jobs_silver.SILVER_APP_SILVER_APPLE_STORE', 'Run Id': 'manual__2025-01-27T23:17:23.147544+00:00', 'Hostname': 'd105ef38d638', 'External Executor Id': '84cd0880-6550-420a-b0bb-f5a3439e3dfa'}
[2025-01-28T00:07:48.642+0000] {logging_mixin.py:151} INFO - [2025-01-28T00:07:48.641+0000] {taskinstance.py:1400} INFO - Marking task as UP_FOR_RETRY. dag_id=dag_d_pipeline_compass_reviews, task_id=group_jobs_silver.SILVER_APP_SILVER_APPLE_STORE, execution_date=20250127T231723, start_date=20250127T233005, end_date=20250128T000748
[2025-01-28T00:07:48.651+0000] {logging_mixin.py:151} INFO - [2025-01-28T00:07:48.651+0000] {configuration.py:1068} WARNING - section/key [smtp/smtp_user] not found in config
[2025-01-28T00:07:48.651+0000] {logging_mixin.py:151} INFO - [2025-01-28T00:07:48.651+0000] {email.py:270} INFO - Email alerting: attempt 1
[2025-01-28T00:07:48.653+0000] {logging_mixin.py:151} INFO - [2025-01-28T00:07:48.653+0000] {configuration.py:1068} WARNING - section/key [smtp/smtp_user] not found in config
[2025-01-28T00:07:48.653+0000] {logging_mixin.py:151} INFO - [2025-01-28T00:07:48.653+0000] {email.py:270} INFO - Email alerting: attempt 1
[2025-01-28T00:07:48.654+0000] {logging_mixin.py:151} INFO - [2025-01-28T00:07:48.654+0000] {taskinstance.py:2007} ERROR - Failed to send email to: ['gacarvalho.contato@gmail.com']
Traceback (most recent call last):
  File "/home/airflow/.local/lib/python3.8/site-packages/airflow/models/taskinstance.py", line 2420, in email_alert
    send_email(task.email, subject, html_content)
  File "/home/airflow/.local/lib/python3.8/site-packages/airflow/utils/email.py", line 80, in send_email
    return backend(
  File "/home/airflow/.local/lib/python3.8/site-packages/airflow/utils/email.py", line 154, in send_email_smtp
    send_mime_email(e_from=mail_from, e_to=recipients, mime_msg=msg, conn_id=conn_id, dryrun=dryrun)
  File "/home/airflow/.local/lib/python3.8/site-packages/airflow/utils/email.py", line 272, in send_mime_email
    smtp_conn = _get_smtp_connection(smtp_host, smtp_port, smtp_timeout, smtp_ssl)
  File "/home/airflow/.local/lib/python3.8/site-packages/airflow/utils/email.py", line 316, in _get_smtp_connection
    return smtplib.SMTP(host=host, port=port, timeout=timeout)
  File "/usr/local/lib/python3.8/smtplib.py", line 255, in __init__
    (code, msg) = self.connect(host, port)
  File "/usr/local/lib/python3.8/smtplib.py", line 339, in connect
    self.sock = self._get_socket(host, port, self.timeout)
  File "/usr/local/lib/python3.8/smtplib.py", line 310, in _get_socket
    return socket.create_connection((host, port), timeout,
  File "/usr/local/lib/python3.8/socket.py", line 808, in create_connection
    raise err
  File "/usr/local/lib/python3.8/socket.py", line 796, in create_connection
    sock.connect(sa)
ConnectionRefusedError: [Errno 111] Connection refused

During handling of the above exception, another exception occurred:

Traceback (most recent call last):
  File "/home/airflow/.local/lib/python3.8/site-packages/airflow/models/taskinstance.py", line 2005, in handle_failure
    self.email_alert(error, task)
  File "/home/airflow/.local/lib/python3.8/site-packages/airflow/models/taskinstance.py", line 2422, in email_alert
    send_email(task.email, subject, html_content_err)
  File "/home/airflow/.local/lib/python3.8/site-packages/airflow/utils/email.py", line 80, in send_email
    return backend(
  File "/home/airflow/.local/lib/python3.8/site-packages/airflow/utils/email.py", line 154, in send_email_smtp
    send_mime_email(e_from=mail_from, e_to=recipients, mime_msg=msg, conn_id=conn_id, dryrun=dryrun)
  File "/home/airflow/.local/lib/python3.8/site-packages/airflow/utils/email.py", line 272, in send_mime_email
    smtp_conn = _get_smtp_connection(smtp_host, smtp_port, smtp_timeout, smtp_ssl)
  File "/home/airflow/.local/lib/python3.8/site-packages/airflow/utils/email.py", line 316, in _get_smtp_connection
    return smtplib.SMTP(host=host, port=port, timeout=timeout)
  File "/usr/local/lib/python3.8/smtplib.py", line 255, in __init__
    (code, msg) = self.connect(host, port)
  File "/usr/local/lib/python3.8/smtplib.py", line 339, in connect
    self.sock = self._get_socket(host, port, self.timeout)
  File "/usr/local/lib/python3.8/smtplib.py", line 310, in _get_socket
    return socket.create_connection((host, port), timeout,
  File "/usr/local/lib/python3.8/socket.py", line 808, in create_connection
    raise err
  File "/usr/local/lib/python3.8/socket.py", line 796, in create_connection
    sock.connect(sa)
ConnectionRefusedError: [Errno 111] Connection refused
[2025-01-28T00:07:48.657+0000] {processor.py:790} INFO - Executed failure callback for <TaskInstance: dag_d_pipeline_compass_reviews.group_jobs_silver.SILVER_APP_SILVER_APPLE_STORE manual__2025-01-27T23:17:23.147544+00:00 [up_for_retry]> in state up_for_retry
[2025-01-28T00:07:48.658+0000] {logging_mixin.py:151} INFO - [2025-01-28T00:07:48.658+0000] {taskinstance.py:1939} ERROR - {'DAG Id': 'dag_d_pipeline_compass_reviews', 'Task Id': 'group_jobs_quality_bronze.B_QUALITY_PIPELINE_APP_REVIEWS_SANTANDER', 'Run Id': 'manual__2025-01-27T23:17:23.147544+00:00', 'Hostname': 'd105ef38d638', 'External Executor Id': '034a974d-0594-4791-83a8-b3aadcde5008'}
[2025-01-28T00:07:48.664+0000] {logging_mixin.py:151} INFO - [2025-01-28T00:07:48.664+0000] {taskinstance.py:1400} INFO - Marking task as UP_FOR_RETRY. dag_id=dag_d_pipeline_compass_reviews, task_id=group_jobs_quality_bronze.B_QUALITY_PIPELINE_APP_REVIEWS_SANTANDER, execution_date=20250127T231723, start_date=20250127T233005, end_date=20250128T000748
[2025-01-28T00:07:48.673+0000] {logging_mixin.py:151} INFO - [2025-01-28T00:07:48.673+0000] {configuration.py:1068} WARNING - section/key [smtp/smtp_user] not found in config
[2025-01-28T00:07:48.673+0000] {logging_mixin.py:151} INFO - [2025-01-28T00:07:48.673+0000] {email.py:270} INFO - Email alerting: attempt 1
[2025-01-28T00:07:48.675+0000] {logging_mixin.py:151} INFO - [2025-01-28T00:07:48.675+0000] {configuration.py:1068} WARNING - section/key [smtp/smtp_user] not found in config
[2025-01-28T00:07:48.675+0000] {logging_mixin.py:151} INFO - [2025-01-28T00:07:48.675+0000] {email.py:270} INFO - Email alerting: attempt 1
[2025-01-28T00:07:48.676+0000] {logging_mixin.py:151} INFO - [2025-01-28T00:07:48.676+0000] {taskinstance.py:2007} ERROR - Failed to send email to: ['gacarvalho.contato@gmail.com']
Traceback (most recent call last):
  File "/home/airflow/.local/lib/python3.8/site-packages/airflow/models/taskinstance.py", line 2420, in email_alert
    send_email(task.email, subject, html_content)
  File "/home/airflow/.local/lib/python3.8/site-packages/airflow/utils/email.py", line 80, in send_email
    return backend(
  File "/home/airflow/.local/lib/python3.8/site-packages/airflow/utils/email.py", line 154, in send_email_smtp
    send_mime_email(e_from=mail_from, e_to=recipients, mime_msg=msg, conn_id=conn_id, dryrun=dryrun)
  File "/home/airflow/.local/lib/python3.8/site-packages/airflow/utils/email.py", line 272, in send_mime_email
    smtp_conn = _get_smtp_connection(smtp_host, smtp_port, smtp_timeout, smtp_ssl)
  File "/home/airflow/.local/lib/python3.8/site-packages/airflow/utils/email.py", line 316, in _get_smtp_connection
    return smtplib.SMTP(host=host, port=port, timeout=timeout)
  File "/usr/local/lib/python3.8/smtplib.py", line 255, in __init__
    (code, msg) = self.connect(host, port)
  File "/usr/local/lib/python3.8/smtplib.py", line 339, in connect
    self.sock = self._get_socket(host, port, self.timeout)
  File "/usr/local/lib/python3.8/smtplib.py", line 310, in _get_socket
    return socket.create_connection((host, port), timeout,
  File "/usr/local/lib/python3.8/socket.py", line 808, in create_connection
    raise err
  File "/usr/local/lib/python3.8/socket.py", line 796, in create_connection
    sock.connect(sa)
ConnectionRefusedError: [Errno 111] Connection refused

During handling of the above exception, another exception occurred:

Traceback (most recent call last):
  File "/home/airflow/.local/lib/python3.8/site-packages/airflow/models/taskinstance.py", line 2005, in handle_failure
    self.email_alert(error, task)
  File "/home/airflow/.local/lib/python3.8/site-packages/airflow/models/taskinstance.py", line 2422, in email_alert
    send_email(task.email, subject, html_content_err)
  File "/home/airflow/.local/lib/python3.8/site-packages/airflow/utils/email.py", line 80, in send_email
    return backend(
  File "/home/airflow/.local/lib/python3.8/site-packages/airflow/utils/email.py", line 154, in send_email_smtp
    send_mime_email(e_from=mail_from, e_to=recipients, mime_msg=msg, conn_id=conn_id, dryrun=dryrun)
  File "/home/airflow/.local/lib/python3.8/site-packages/airflow/utils/email.py", line 272, in send_mime_email
    smtp_conn = _get_smtp_connection(smtp_host, smtp_port, smtp_timeout, smtp_ssl)
  File "/home/airflow/.local/lib/python3.8/site-packages/airflow/utils/email.py", line 316, in _get_smtp_connection
    return smtplib.SMTP(host=host, port=port, timeout=timeout)
  File "/usr/local/lib/python3.8/smtplib.py", line 255, in __init__
    (code, msg) = self.connect(host, port)
  File "/usr/local/lib/python3.8/smtplib.py", line 339, in connect
    self.sock = self._get_socket(host, port, self.timeout)
  File "/usr/local/lib/python3.8/smtplib.py", line 310, in _get_socket
    return socket.create_connection((host, port), timeout,
  File "/usr/local/lib/python3.8/socket.py", line 808, in create_connection
    raise err
  File "/usr/local/lib/python3.8/socket.py", line 796, in create_connection
    sock.connect(sa)
ConnectionRefusedError: [Errno 111] Connection refused
[2025-01-28T00:07:48.687+0000] {processor.py:790} INFO - Executed failure callback for <TaskInstance: dag_d_pipeline_compass_reviews.group_jobs_quality_bronze.B_QUALITY_PIPELINE_APP_REVIEWS_SANTANDER manual__2025-01-27T23:17:23.147544+00:00 [up_for_retry]> in state up_for_retry
[2025-01-28T00:07:48.689+0000] {logging_mixin.py:151} INFO - [2025-01-28T00:07:48.689+0000] {taskinstance.py:1939} ERROR - {'DAG Id': 'dag_d_pipeline_compass_reviews', 'Task Id': 'group_jobs_silver.SILVER_APP_SILVER_GOOGLE_PLAY', 'Run Id': 'manual__2025-01-27T23:17:23.147544+00:00', 'Hostname': 'd105ef38d638', 'External Executor Id': '7039e3b4-34cc-48a7-a70f-c83fb6bec985'}
[2025-01-28T00:07:48.694+0000] {logging_mixin.py:151} INFO - [2025-01-28T00:07:48.694+0000] {taskinstance.py:1400} INFO - Marking task as FAILED. dag_id=dag_d_pipeline_compass_reviews, task_id=group_jobs_silver.SILVER_APP_SILVER_GOOGLE_PLAY, execution_date=20250127T231723, start_date=20250127T232714, end_date=20250128T000748
[2025-01-28T00:07:48.705+0000] {logging_mixin.py:151} INFO - [2025-01-28T00:07:48.705+0000] {configuration.py:1068} WARNING - section/key [smtp/smtp_user] not found in config
[2025-01-28T00:07:48.705+0000] {logging_mixin.py:151} INFO - [2025-01-28T00:07:48.705+0000] {email.py:270} INFO - Email alerting: attempt 1
[2025-01-28T00:07:48.708+0000] {logging_mixin.py:151} INFO - [2025-01-28T00:07:48.708+0000] {configuration.py:1068} WARNING - section/key [smtp/smtp_user] not found in config
[2025-01-28T00:07:48.708+0000] {logging_mixin.py:151} INFO - [2025-01-28T00:07:48.708+0000] {email.py:270} INFO - Email alerting: attempt 1
[2025-01-28T00:07:48.709+0000] {logging_mixin.py:151} INFO - [2025-01-28T00:07:48.708+0000] {taskinstance.py:2007} ERROR - Failed to send email to: ['gacarvalho.contato@gmail.com']
Traceback (most recent call last):
  File "/home/airflow/.local/lib/python3.8/site-packages/airflow/models/taskinstance.py", line 2420, in email_alert
    send_email(task.email, subject, html_content)
  File "/home/airflow/.local/lib/python3.8/site-packages/airflow/utils/email.py", line 80, in send_email
    return backend(
  File "/home/airflow/.local/lib/python3.8/site-packages/airflow/utils/email.py", line 154, in send_email_smtp
    send_mime_email(e_from=mail_from, e_to=recipients, mime_msg=msg, conn_id=conn_id, dryrun=dryrun)
  File "/home/airflow/.local/lib/python3.8/site-packages/airflow/utils/email.py", line 272, in send_mime_email
    smtp_conn = _get_smtp_connection(smtp_host, smtp_port, smtp_timeout, smtp_ssl)
  File "/home/airflow/.local/lib/python3.8/site-packages/airflow/utils/email.py", line 316, in _get_smtp_connection
    return smtplib.SMTP(host=host, port=port, timeout=timeout)
  File "/usr/local/lib/python3.8/smtplib.py", line 255, in __init__
    (code, msg) = self.connect(host, port)
  File "/usr/local/lib/python3.8/smtplib.py", line 339, in connect
    self.sock = self._get_socket(host, port, self.timeout)
  File "/usr/local/lib/python3.8/smtplib.py", line 310, in _get_socket
    return socket.create_connection((host, port), timeout,
  File "/usr/local/lib/python3.8/socket.py", line 808, in create_connection
    raise err
  File "/usr/local/lib/python3.8/socket.py", line 796, in create_connection
    sock.connect(sa)
ConnectionRefusedError: [Errno 111] Connection refused

During handling of the above exception, another exception occurred:

Traceback (most recent call last):
  File "/home/airflow/.local/lib/python3.8/site-packages/airflow/models/taskinstance.py", line 2005, in handle_failure
    self.email_alert(error, task)
  File "/home/airflow/.local/lib/python3.8/site-packages/airflow/models/taskinstance.py", line 2422, in email_alert
    send_email(task.email, subject, html_content_err)
  File "/home/airflow/.local/lib/python3.8/site-packages/airflow/utils/email.py", line 80, in send_email
    return backend(
  File "/home/airflow/.local/lib/python3.8/site-packages/airflow/utils/email.py", line 154, in send_email_smtp
    send_mime_email(e_from=mail_from, e_to=recipients, mime_msg=msg, conn_id=conn_id, dryrun=dryrun)
  File "/home/airflow/.local/lib/python3.8/site-packages/airflow/utils/email.py", line 272, in send_mime_email
    smtp_conn = _get_smtp_connection(smtp_host, smtp_port, smtp_timeout, smtp_ssl)
  File "/home/airflow/.local/lib/python3.8/site-packages/airflow/utils/email.py", line 316, in _get_smtp_connection
    return smtplib.SMTP(host=host, port=port, timeout=timeout)
  File "/usr/local/lib/python3.8/smtplib.py", line 255, in __init__
    (code, msg) = self.connect(host, port)
  File "/usr/local/lib/python3.8/smtplib.py", line 339, in connect
    self.sock = self._get_socket(host, port, self.timeout)
  File "/usr/local/lib/python3.8/smtplib.py", line 310, in _get_socket
    return socket.create_connection((host, port), timeout,
  File "/usr/local/lib/python3.8/socket.py", line 808, in create_connection
    raise err
  File "/usr/local/lib/python3.8/socket.py", line 796, in create_connection
    sock.connect(sa)
ConnectionRefusedError: [Errno 111] Connection refused
[2025-01-28T00:07:48.712+0000] {processor.py:790} INFO - Executed failure callback for <TaskInstance: dag_d_pipeline_compass_reviews.group_jobs_silver.SILVER_APP_SILVER_GOOGLE_PLAY manual__2025-01-27T23:17:23.147544+00:00 [failed]> in state failed
[2025-01-28T00:07:48.734+0000] {logging_mixin.py:151} INFO - [2025-01-28T00:07:48.734+0000] {dag.py:2941} INFO - Sync 1 DAGs
[2025-01-28T00:07:48.757+0000] {logging_mixin.py:151} INFO - [2025-01-28T00:07:48.757+0000] {dag.py:3722} INFO - Setting next_dagrun for dag_d_pipeline_compass_reviews to 2025-01-27T06:00:00+00:00, run_after=2025-01-28T06:00:00+00:00
[2025-01-28T00:07:48.802+0000] {processor.py:179} INFO - Processing /opt/airflow/dags/dag_d_pipeline_compass_reviews.py took 0.260 seconds
[2025-01-28T00:08:19.688+0000] {processor.py:157} INFO - Started process (PID=36) to work on /opt/airflow/dags/dag_d_pipeline_compass_reviews.py
[2025-01-28T00:08:19.689+0000] {processor.py:829} INFO - Processing file /opt/airflow/dags/dag_d_pipeline_compass_reviews.py for tasks to queue
[2025-01-28T00:08:19.691+0000] {logging_mixin.py:151} INFO - [2025-01-28T00:08:19.691+0000] {dagbag.py:536} INFO - Filling up the DagBag from /opt/airflow/dags/dag_d_pipeline_compass_reviews.py
[2025-01-28T00:08:19.702+0000] {logging_mixin.py:151} WARNING - /home/airflow/.local/lib/python3.8/site-packages/airflow/operators/python.py:177 RemovedInAirflow3Warning: The 'task_concurrency' parameter is deprecated. Please use 'max_active_tis_per_dag'.
[2025-01-28T00:08:19.709+0000] {processor.py:839} INFO - DAG(s) dict_keys(['dag_d_pipeline_compass_reviews']) retrieved from /opt/airflow/dags/dag_d_pipeline_compass_reviews.py
[2025-01-28T00:08:19.727+0000] {logging_mixin.py:151} INFO - [2025-01-28T00:08:19.727+0000] {taskinstance.py:1939} ERROR - {'DAG Id': 'dag_d_pipeline_compass_reviews', 'Task Id': 'group_jobs_silver.SILVER_APP_SILVER_APPLE_STORE', 'Run Id': 'manual__2025-01-27T23:17:23.147544+00:00', 'Hostname': 'd105ef38d638', 'External Executor Id': '84cd0880-6550-420a-b0bb-f5a3439e3dfa'}
[2025-01-28T00:08:19.739+0000] {logging_mixin.py:151} INFO - [2025-01-28T00:08:19.739+0000] {taskinstance.py:1400} INFO - Marking task as FAILED. dag_id=dag_d_pipeline_compass_reviews, task_id=group_jobs_silver.SILVER_APP_SILVER_APPLE_STORE, execution_date=20250127T231723, start_date=20250127T233005, end_date=20250128T000819
[2025-01-28T00:08:19.753+0000] {logging_mixin.py:151} WARNING - /home/airflow/.local/lib/python3.8/site-packages/airflow/utils/email.py:154 RemovedInAirflow3Warning: Fetching SMTP credentials from configuration variables will be deprecated in a future release. Please set credentials using a connection instead.
[2025-01-28T00:08:19.753+0000] {logging_mixin.py:151} INFO - [2025-01-28T00:08:19.753+0000] {configuration.py:1068} WARNING - section/key [smtp/smtp_user] not found in config
[2025-01-28T00:08:19.753+0000] {logging_mixin.py:151} INFO - [2025-01-28T00:08:19.753+0000] {email.py:270} INFO - Email alerting: attempt 1
[2025-01-28T00:08:19.755+0000] {logging_mixin.py:151} INFO - [2025-01-28T00:08:19.755+0000] {configuration.py:1068} WARNING - section/key [smtp/smtp_user] not found in config
[2025-01-28T00:08:19.755+0000] {logging_mixin.py:151} INFO - [2025-01-28T00:08:19.755+0000] {email.py:270} INFO - Email alerting: attempt 1
[2025-01-28T00:08:19.757+0000] {logging_mixin.py:151} INFO - [2025-01-28T00:08:19.756+0000] {taskinstance.py:2007} ERROR - Failed to send email to: ['gacarvalho.contato@gmail.com']
Traceback (most recent call last):
  File "/home/airflow/.local/lib/python3.8/site-packages/airflow/models/taskinstance.py", line 2420, in email_alert
    send_email(task.email, subject, html_content)
  File "/home/airflow/.local/lib/python3.8/site-packages/airflow/utils/email.py", line 80, in send_email
    return backend(
  File "/home/airflow/.local/lib/python3.8/site-packages/airflow/utils/email.py", line 154, in send_email_smtp
    send_mime_email(e_from=mail_from, e_to=recipients, mime_msg=msg, conn_id=conn_id, dryrun=dryrun)
  File "/home/airflow/.local/lib/python3.8/site-packages/airflow/utils/email.py", line 272, in send_mime_email
    smtp_conn = _get_smtp_connection(smtp_host, smtp_port, smtp_timeout, smtp_ssl)
  File "/home/airflow/.local/lib/python3.8/site-packages/airflow/utils/email.py", line 316, in _get_smtp_connection
    return smtplib.SMTP(host=host, port=port, timeout=timeout)
  File "/usr/local/lib/python3.8/smtplib.py", line 255, in __init__
    (code, msg) = self.connect(host, port)
  File "/usr/local/lib/python3.8/smtplib.py", line 339, in connect
    self.sock = self._get_socket(host, port, self.timeout)
  File "/usr/local/lib/python3.8/smtplib.py", line 310, in _get_socket
    return socket.create_connection((host, port), timeout,
  File "/usr/local/lib/python3.8/socket.py", line 808, in create_connection
    raise err
  File "/usr/local/lib/python3.8/socket.py", line 796, in create_connection
    sock.connect(sa)
ConnectionRefusedError: [Errno 111] Connection refused

During handling of the above exception, another exception occurred:

Traceback (most recent call last):
  File "/home/airflow/.local/lib/python3.8/site-packages/airflow/models/taskinstance.py", line 2005, in handle_failure
    self.email_alert(error, task)
  File "/home/airflow/.local/lib/python3.8/site-packages/airflow/models/taskinstance.py", line 2422, in email_alert
    send_email(task.email, subject, html_content_err)
  File "/home/airflow/.local/lib/python3.8/site-packages/airflow/utils/email.py", line 80, in send_email
    return backend(
  File "/home/airflow/.local/lib/python3.8/site-packages/airflow/utils/email.py", line 154, in send_email_smtp
    send_mime_email(e_from=mail_from, e_to=recipients, mime_msg=msg, conn_id=conn_id, dryrun=dryrun)
  File "/home/airflow/.local/lib/python3.8/site-packages/airflow/utils/email.py", line 272, in send_mime_email
    smtp_conn = _get_smtp_connection(smtp_host, smtp_port, smtp_timeout, smtp_ssl)
  File "/home/airflow/.local/lib/python3.8/site-packages/airflow/utils/email.py", line 316, in _get_smtp_connection
    return smtplib.SMTP(host=host, port=port, timeout=timeout)
  File "/usr/local/lib/python3.8/smtplib.py", line 255, in __init__
    (code, msg) = self.connect(host, port)
  File "/usr/local/lib/python3.8/smtplib.py", line 339, in connect
    self.sock = self._get_socket(host, port, self.timeout)
  File "/usr/local/lib/python3.8/smtplib.py", line 310, in _get_socket
    return socket.create_connection((host, port), timeout,
  File "/usr/local/lib/python3.8/socket.py", line 808, in create_connection
    raise err
  File "/usr/local/lib/python3.8/socket.py", line 796, in create_connection
    sock.connect(sa)
ConnectionRefusedError: [Errno 111] Connection refused
[2025-01-28T00:08:19.766+0000] {processor.py:790} INFO - Executed failure callback for <TaskInstance: dag_d_pipeline_compass_reviews.group_jobs_silver.SILVER_APP_SILVER_APPLE_STORE manual__2025-01-27T23:17:23.147544+00:00 [failed]> in state failed
[2025-01-28T00:08:19.768+0000] {logging_mixin.py:151} INFO - [2025-01-28T00:08:19.768+0000] {taskinstance.py:1939} ERROR - {'DAG Id': 'dag_d_pipeline_compass_reviews', 'Task Id': 'group_jobs_quality_bronze.B_QUALITY_PIPELINE_APP_REVIEWS_SANTANDER', 'Run Id': 'manual__2025-01-27T23:17:23.147544+00:00', 'Hostname': 'd105ef38d638', 'External Executor Id': '034a974d-0594-4791-83a8-b3aadcde5008'}
[2025-01-28T00:08:19.773+0000] {logging_mixin.py:151} INFO - [2025-01-28T00:08:19.773+0000] {taskinstance.py:1400} INFO - Marking task as FAILED. dag_id=dag_d_pipeline_compass_reviews, task_id=group_jobs_quality_bronze.B_QUALITY_PIPELINE_APP_REVIEWS_SANTANDER, execution_date=20250127T231723, start_date=20250127T233005, end_date=20250128T000819
[2025-01-28T00:08:19.783+0000] {logging_mixin.py:151} INFO - [2025-01-28T00:08:19.783+0000] {configuration.py:1068} WARNING - section/key [smtp/smtp_user] not found in config
[2025-01-28T00:08:19.784+0000] {logging_mixin.py:151} INFO - [2025-01-28T00:08:19.784+0000] {email.py:270} INFO - Email alerting: attempt 1
[2025-01-28T00:08:19.786+0000] {logging_mixin.py:151} INFO - [2025-01-28T00:08:19.786+0000] {configuration.py:1068} WARNING - section/key [smtp/smtp_user] not found in config
[2025-01-28T00:08:19.786+0000] {logging_mixin.py:151} INFO - [2025-01-28T00:08:19.786+0000] {email.py:270} INFO - Email alerting: attempt 1
[2025-01-28T00:08:19.787+0000] {logging_mixin.py:151} INFO - [2025-01-28T00:08:19.786+0000] {taskinstance.py:2007} ERROR - Failed to send email to: ['gacarvalho.contato@gmail.com']
Traceback (most recent call last):
  File "/home/airflow/.local/lib/python3.8/site-packages/airflow/models/taskinstance.py", line 2420, in email_alert
    send_email(task.email, subject, html_content)
  File "/home/airflow/.local/lib/python3.8/site-packages/airflow/utils/email.py", line 80, in send_email
    return backend(
  File "/home/airflow/.local/lib/python3.8/site-packages/airflow/utils/email.py", line 154, in send_email_smtp
    send_mime_email(e_from=mail_from, e_to=recipients, mime_msg=msg, conn_id=conn_id, dryrun=dryrun)
  File "/home/airflow/.local/lib/python3.8/site-packages/airflow/utils/email.py", line 272, in send_mime_email
    smtp_conn = _get_smtp_connection(smtp_host, smtp_port, smtp_timeout, smtp_ssl)
  File "/home/airflow/.local/lib/python3.8/site-packages/airflow/utils/email.py", line 316, in _get_smtp_connection
    return smtplib.SMTP(host=host, port=port, timeout=timeout)
  File "/usr/local/lib/python3.8/smtplib.py", line 255, in __init__
    (code, msg) = self.connect(host, port)
  File "/usr/local/lib/python3.8/smtplib.py", line 339, in connect
    self.sock = self._get_socket(host, port, self.timeout)
  File "/usr/local/lib/python3.8/smtplib.py", line 310, in _get_socket
    return socket.create_connection((host, port), timeout,
  File "/usr/local/lib/python3.8/socket.py", line 808, in create_connection
    raise err
  File "/usr/local/lib/python3.8/socket.py", line 796, in create_connection
    sock.connect(sa)
ConnectionRefusedError: [Errno 111] Connection refused

During handling of the above exception, another exception occurred:

Traceback (most recent call last):
  File "/home/airflow/.local/lib/python3.8/site-packages/airflow/models/taskinstance.py", line 2005, in handle_failure
    self.email_alert(error, task)
  File "/home/airflow/.local/lib/python3.8/site-packages/airflow/models/taskinstance.py", line 2422, in email_alert
    send_email(task.email, subject, html_content_err)
  File "/home/airflow/.local/lib/python3.8/site-packages/airflow/utils/email.py", line 80, in send_email
    return backend(
  File "/home/airflow/.local/lib/python3.8/site-packages/airflow/utils/email.py", line 154, in send_email_smtp
    send_mime_email(e_from=mail_from, e_to=recipients, mime_msg=msg, conn_id=conn_id, dryrun=dryrun)
  File "/home/airflow/.local/lib/python3.8/site-packages/airflow/utils/email.py", line 272, in send_mime_email
    smtp_conn = _get_smtp_connection(smtp_host, smtp_port, smtp_timeout, smtp_ssl)
  File "/home/airflow/.local/lib/python3.8/site-packages/airflow/utils/email.py", line 316, in _get_smtp_connection
    return smtplib.SMTP(host=host, port=port, timeout=timeout)
  File "/usr/local/lib/python3.8/smtplib.py", line 255, in __init__
    (code, msg) = self.connect(host, port)
  File "/usr/local/lib/python3.8/smtplib.py", line 339, in connect
    self.sock = self._get_socket(host, port, self.timeout)
  File "/usr/local/lib/python3.8/smtplib.py", line 310, in _get_socket
    return socket.create_connection((host, port), timeout,
  File "/usr/local/lib/python3.8/socket.py", line 808, in create_connection
    raise err
  File "/usr/local/lib/python3.8/socket.py", line 796, in create_connection
    sock.connect(sa)
ConnectionRefusedError: [Errno 111] Connection refused
[2025-01-28T00:08:19.790+0000] {processor.py:790} INFO - Executed failure callback for <TaskInstance: dag_d_pipeline_compass_reviews.group_jobs_quality_bronze.B_QUALITY_PIPELINE_APP_REVIEWS_SANTANDER manual__2025-01-27T23:17:23.147544+00:00 [failed]> in state failed
[2025-01-28T00:08:19.808+0000] {logging_mixin.py:151} INFO - [2025-01-28T00:08:19.807+0000] {dag.py:2941} INFO - Sync 1 DAGs
[2025-01-28T00:08:19.823+0000] {logging_mixin.py:151} INFO - [2025-01-28T00:08:19.823+0000] {dag.py:3722} INFO - Setting next_dagrun for dag_d_pipeline_compass_reviews to 2025-01-27T06:00:00+00:00, run_after=2025-01-28T06:00:00+00:00
[2025-01-28T00:08:19.837+0000] {processor.py:179} INFO - Processing /opt/airflow/dags/dag_d_pipeline_compass_reviews.py took 0.153 seconds
[2025-01-28T00:08:49.977+0000] {processor.py:157} INFO - Started process (PID=39) to work on /opt/airflow/dags/dag_d_pipeline_compass_reviews.py
[2025-01-28T00:08:49.978+0000] {processor.py:829} INFO - Processing file /opt/airflow/dags/dag_d_pipeline_compass_reviews.py for tasks to queue
[2025-01-28T00:08:49.980+0000] {logging_mixin.py:151} INFO - [2025-01-28T00:08:49.980+0000] {dagbag.py:536} INFO - Filling up the DagBag from /opt/airflow/dags/dag_d_pipeline_compass_reviews.py
[2025-01-28T00:08:49.991+0000] {logging_mixin.py:151} WARNING - /home/airflow/.local/lib/python3.8/site-packages/airflow/operators/python.py:177 RemovedInAirflow3Warning: The 'task_concurrency' parameter is deprecated. Please use 'max_active_tis_per_dag'.
[2025-01-28T00:08:49.998+0000] {processor.py:839} INFO - DAG(s) dict_keys(['dag_d_pipeline_compass_reviews']) retrieved from /opt/airflow/dags/dag_d_pipeline_compass_reviews.py
[2025-01-28T00:08:50.022+0000] {logging_mixin.py:151} INFO - [2025-01-28T00:08:50.022+0000] {dag.py:2941} INFO - Sync 1 DAGs
[2025-01-28T00:08:50.040+0000] {logging_mixin.py:151} INFO - [2025-01-28T00:08:50.040+0000] {dag.py:3722} INFO - Setting next_dagrun for dag_d_pipeline_compass_reviews to 2025-01-27T06:00:00+00:00, run_after=2025-01-28T06:00:00+00:00
[2025-01-28T00:08:50.060+0000] {processor.py:179} INFO - Processing /opt/airflow/dags/dag_d_pipeline_compass_reviews.py took 0.085 seconds
[2025-01-28T00:09:20.198+0000] {processor.py:157} INFO - Started process (PID=42) to work on /opt/airflow/dags/dag_d_pipeline_compass_reviews.py
[2025-01-28T00:09:20.198+0000] {processor.py:829} INFO - Processing file /opt/airflow/dags/dag_d_pipeline_compass_reviews.py for tasks to queue
[2025-01-28T00:09:20.200+0000] {logging_mixin.py:151} INFO - [2025-01-28T00:09:20.200+0000] {dagbag.py:536} INFO - Filling up the DagBag from /opt/airflow/dags/dag_d_pipeline_compass_reviews.py
[2025-01-28T00:09:20.210+0000] {logging_mixin.py:151} WARNING - /home/airflow/.local/lib/python3.8/site-packages/airflow/operators/python.py:177 RemovedInAirflow3Warning: The 'task_concurrency' parameter is deprecated. Please use 'max_active_tis_per_dag'.
[2025-01-28T00:09:20.215+0000] {processor.py:839} INFO - DAG(s) dict_keys(['dag_d_pipeline_compass_reviews']) retrieved from /opt/airflow/dags/dag_d_pipeline_compass_reviews.py
[2025-01-28T00:09:20.238+0000] {logging_mixin.py:151} INFO - [2025-01-28T00:09:20.238+0000] {dag.py:2941} INFO - Sync 1 DAGs
[2025-01-28T00:09:20.254+0000] {logging_mixin.py:151} INFO - [2025-01-28T00:09:20.254+0000] {dag.py:3722} INFO - Setting next_dagrun for dag_d_pipeline_compass_reviews to 2025-01-27T06:00:00+00:00, run_after=2025-01-28T06:00:00+00:00
[2025-01-28T00:09:20.269+0000] {processor.py:179} INFO - Processing /opt/airflow/dags/dag_d_pipeline_compass_reviews.py took 0.074 seconds
[2025-01-28T00:09:50.448+0000] {processor.py:157} INFO - Started process (PID=45) to work on /opt/airflow/dags/dag_d_pipeline_compass_reviews.py
[2025-01-28T00:09:50.449+0000] {processor.py:829} INFO - Processing file /opt/airflow/dags/dag_d_pipeline_compass_reviews.py for tasks to queue
[2025-01-28T00:09:50.451+0000] {logging_mixin.py:151} INFO - [2025-01-28T00:09:50.451+0000] {dagbag.py:536} INFO - Filling up the DagBag from /opt/airflow/dags/dag_d_pipeline_compass_reviews.py
[2025-01-28T00:09:50.461+0000] {logging_mixin.py:151} WARNING - /home/airflow/.local/lib/python3.8/site-packages/airflow/operators/python.py:177 RemovedInAirflow3Warning: The 'task_concurrency' parameter is deprecated. Please use 'max_active_tis_per_dag'.
[2025-01-28T00:09:50.466+0000] {processor.py:839} INFO - DAG(s) dict_keys(['dag_d_pipeline_compass_reviews']) retrieved from /opt/airflow/dags/dag_d_pipeline_compass_reviews.py
[2025-01-28T00:09:50.491+0000] {logging_mixin.py:151} INFO - [2025-01-28T00:09:50.491+0000] {dag.py:2941} INFO - Sync 1 DAGs
[2025-01-28T00:09:50.525+0000] {logging_mixin.py:151} INFO - [2025-01-28T00:09:50.525+0000] {dag.py:3722} INFO - Setting next_dagrun for dag_d_pipeline_compass_reviews to 2025-01-27T06:00:00+00:00, run_after=2025-01-28T06:00:00+00:00
[2025-01-28T00:09:50.540+0000] {processor.py:179} INFO - Processing /opt/airflow/dags/dag_d_pipeline_compass_reviews.py took 0.094 seconds
[2025-01-28T00:10:20.640+0000] {processor.py:157} INFO - Started process (PID=48) to work on /opt/airflow/dags/dag_d_pipeline_compass_reviews.py
[2025-01-28T00:10:20.641+0000] {processor.py:829} INFO - Processing file /opt/airflow/dags/dag_d_pipeline_compass_reviews.py for tasks to queue
[2025-01-28T00:10:20.642+0000] {logging_mixin.py:151} INFO - [2025-01-28T00:10:20.642+0000] {dagbag.py:536} INFO - Filling up the DagBag from /opt/airflow/dags/dag_d_pipeline_compass_reviews.py
[2025-01-28T00:10:20.652+0000] {logging_mixin.py:151} WARNING - /home/airflow/.local/lib/python3.8/site-packages/airflow/operators/python.py:177 RemovedInAirflow3Warning: The 'task_concurrency' parameter is deprecated. Please use 'max_active_tis_per_dag'.
[2025-01-28T00:10:20.657+0000] {processor.py:839} INFO - DAG(s) dict_keys(['dag_d_pipeline_compass_reviews']) retrieved from /opt/airflow/dags/dag_d_pipeline_compass_reviews.py
[2025-01-28T00:10:20.680+0000] {logging_mixin.py:151} INFO - [2025-01-28T00:10:20.680+0000] {dag.py:2941} INFO - Sync 1 DAGs
[2025-01-28T00:10:20.698+0000] {logging_mixin.py:151} INFO - [2025-01-28T00:10:20.698+0000] {dag.py:3722} INFO - Setting next_dagrun for dag_d_pipeline_compass_reviews to 2025-01-27T06:00:00+00:00, run_after=2025-01-28T06:00:00+00:00
[2025-01-28T00:10:20.716+0000] {processor.py:179} INFO - Processing /opt/airflow/dags/dag_d_pipeline_compass_reviews.py took 0.078 seconds
[2025-01-28T00:10:50.841+0000] {processor.py:157} INFO - Started process (PID=51) to work on /opt/airflow/dags/dag_d_pipeline_compass_reviews.py
[2025-01-28T00:10:50.841+0000] {processor.py:829} INFO - Processing file /opt/airflow/dags/dag_d_pipeline_compass_reviews.py for tasks to queue
[2025-01-28T00:10:50.843+0000] {logging_mixin.py:151} INFO - [2025-01-28T00:10:50.843+0000] {dagbag.py:536} INFO - Filling up the DagBag from /opt/airflow/dags/dag_d_pipeline_compass_reviews.py
[2025-01-28T00:10:50.853+0000] {logging_mixin.py:151} WARNING - /home/airflow/.local/lib/python3.8/site-packages/airflow/operators/python.py:177 RemovedInAirflow3Warning: The 'task_concurrency' parameter is deprecated. Please use 'max_active_tis_per_dag'.
[2025-01-28T00:10:50.859+0000] {processor.py:839} INFO - DAG(s) dict_keys(['dag_d_pipeline_compass_reviews']) retrieved from /opt/airflow/dags/dag_d_pipeline_compass_reviews.py
[2025-01-28T00:10:50.885+0000] {logging_mixin.py:151} INFO - [2025-01-28T00:10:50.885+0000] {dag.py:2941} INFO - Sync 1 DAGs
[2025-01-28T00:10:50.903+0000] {logging_mixin.py:151} INFO - [2025-01-28T00:10:50.903+0000] {dag.py:3722} INFO - Setting next_dagrun for dag_d_pipeline_compass_reviews to 2025-01-27T06:00:00+00:00, run_after=2025-01-28T06:00:00+00:00
[2025-01-28T00:10:50.921+0000] {processor.py:179} INFO - Processing /opt/airflow/dags/dag_d_pipeline_compass_reviews.py took 0.082 seconds
[2025-01-28T00:11:21.031+0000] {processor.py:157} INFO - Started process (PID=54) to work on /opt/airflow/dags/dag_d_pipeline_compass_reviews.py
[2025-01-28T00:11:21.032+0000] {processor.py:829} INFO - Processing file /opt/airflow/dags/dag_d_pipeline_compass_reviews.py for tasks to queue
[2025-01-28T00:11:21.033+0000] {logging_mixin.py:151} INFO - [2025-01-28T00:11:21.033+0000] {dagbag.py:536} INFO - Filling up the DagBag from /opt/airflow/dags/dag_d_pipeline_compass_reviews.py
[2025-01-28T00:11:21.043+0000] {logging_mixin.py:151} WARNING - /home/airflow/.local/lib/python3.8/site-packages/airflow/operators/python.py:177 RemovedInAirflow3Warning: The 'task_concurrency' parameter is deprecated. Please use 'max_active_tis_per_dag'.
[2025-01-28T00:11:21.049+0000] {processor.py:839} INFO - DAG(s) dict_keys(['dag_d_pipeline_compass_reviews']) retrieved from /opt/airflow/dags/dag_d_pipeline_compass_reviews.py
[2025-01-28T00:11:21.076+0000] {logging_mixin.py:151} INFO - [2025-01-28T00:11:21.076+0000] {dag.py:2941} INFO - Sync 1 DAGs
[2025-01-28T00:11:21.093+0000] {logging_mixin.py:151} INFO - [2025-01-28T00:11:21.093+0000] {dag.py:3722} INFO - Setting next_dagrun for dag_d_pipeline_compass_reviews to 2025-01-27T06:00:00+00:00, run_after=2025-01-28T06:00:00+00:00
[2025-01-28T00:11:21.111+0000] {processor.py:179} INFO - Processing /opt/airflow/dags/dag_d_pipeline_compass_reviews.py took 0.082 seconds
[2025-01-28T00:11:51.258+0000] {processor.py:157} INFO - Started process (PID=57) to work on /opt/airflow/dags/dag_d_pipeline_compass_reviews.py
[2025-01-28T00:11:51.259+0000] {processor.py:829} INFO - Processing file /opt/airflow/dags/dag_d_pipeline_compass_reviews.py for tasks to queue
[2025-01-28T00:11:51.260+0000] {logging_mixin.py:151} INFO - [2025-01-28T00:11:51.260+0000] {dagbag.py:536} INFO - Filling up the DagBag from /opt/airflow/dags/dag_d_pipeline_compass_reviews.py
[2025-01-28T00:11:51.271+0000] {logging_mixin.py:151} WARNING - /home/airflow/.local/lib/python3.8/site-packages/airflow/operators/python.py:177 RemovedInAirflow3Warning: The 'task_concurrency' parameter is deprecated. Please use 'max_active_tis_per_dag'.
[2025-01-28T00:11:51.277+0000] {processor.py:839} INFO - DAG(s) dict_keys(['dag_d_pipeline_compass_reviews']) retrieved from /opt/airflow/dags/dag_d_pipeline_compass_reviews.py
[2025-01-28T00:11:51.302+0000] {logging_mixin.py:151} INFO - [2025-01-28T00:11:51.302+0000] {dag.py:2941} INFO - Sync 1 DAGs
[2025-01-28T00:11:51.319+0000] {logging_mixin.py:151} INFO - [2025-01-28T00:11:51.319+0000] {dag.py:3722} INFO - Setting next_dagrun for dag_d_pipeline_compass_reviews to 2025-01-27T06:00:00+00:00, run_after=2025-01-28T06:00:00+00:00
[2025-01-28T00:11:51.335+0000] {processor.py:179} INFO - Processing /opt/airflow/dags/dag_d_pipeline_compass_reviews.py took 0.079 seconds
[2025-01-28T00:12:21.452+0000] {processor.py:157} INFO - Started process (PID=60) to work on /opt/airflow/dags/dag_d_pipeline_compass_reviews.py
[2025-01-28T00:12:21.453+0000] {processor.py:829} INFO - Processing file /opt/airflow/dags/dag_d_pipeline_compass_reviews.py for tasks to queue
[2025-01-28T00:12:21.455+0000] {logging_mixin.py:151} INFO - [2025-01-28T00:12:21.454+0000] {dagbag.py:536} INFO - Filling up the DagBag from /opt/airflow/dags/dag_d_pipeline_compass_reviews.py
[2025-01-28T00:12:21.466+0000] {logging_mixin.py:151} WARNING - /home/airflow/.local/lib/python3.8/site-packages/airflow/operators/python.py:177 RemovedInAirflow3Warning: The 'task_concurrency' parameter is deprecated. Please use 'max_active_tis_per_dag'.
[2025-01-28T00:12:21.472+0000] {processor.py:839} INFO - DAG(s) dict_keys(['dag_d_pipeline_compass_reviews']) retrieved from /opt/airflow/dags/dag_d_pipeline_compass_reviews.py
[2025-01-28T00:12:21.503+0000] {logging_mixin.py:151} INFO - [2025-01-28T00:12:21.503+0000] {dag.py:2941} INFO - Sync 1 DAGs
[2025-01-28T00:12:21.522+0000] {logging_mixin.py:151} INFO - [2025-01-28T00:12:21.521+0000] {dag.py:3722} INFO - Setting next_dagrun for dag_d_pipeline_compass_reviews to 2025-01-27T06:00:00+00:00, run_after=2025-01-28T06:00:00+00:00
[2025-01-28T00:12:21.536+0000] {processor.py:179} INFO - Processing /opt/airflow/dags/dag_d_pipeline_compass_reviews.py took 0.087 seconds
[2025-01-28T00:12:51.670+0000] {processor.py:157} INFO - Started process (PID=63) to work on /opt/airflow/dags/dag_d_pipeline_compass_reviews.py
[2025-01-28T00:12:51.671+0000] {processor.py:829} INFO - Processing file /opt/airflow/dags/dag_d_pipeline_compass_reviews.py for tasks to queue
[2025-01-28T00:12:51.673+0000] {logging_mixin.py:151} INFO - [2025-01-28T00:12:51.672+0000] {dagbag.py:536} INFO - Filling up the DagBag from /opt/airflow/dags/dag_d_pipeline_compass_reviews.py
[2025-01-28T00:12:51.682+0000] {logging_mixin.py:151} WARNING - /home/airflow/.local/lib/python3.8/site-packages/airflow/operators/python.py:177 RemovedInAirflow3Warning: The 'task_concurrency' parameter is deprecated. Please use 'max_active_tis_per_dag'.
[2025-01-28T00:12:51.688+0000] {processor.py:839} INFO - DAG(s) dict_keys(['dag_d_pipeline_compass_reviews']) retrieved from /opt/airflow/dags/dag_d_pipeline_compass_reviews.py
[2025-01-28T00:12:51.711+0000] {logging_mixin.py:151} INFO - [2025-01-28T00:12:51.711+0000] {dag.py:2941} INFO - Sync 1 DAGs
[2025-01-28T00:12:51.729+0000] {logging_mixin.py:151} INFO - [2025-01-28T00:12:51.728+0000] {dag.py:3722} INFO - Setting next_dagrun for dag_d_pipeline_compass_reviews to 2025-01-27T06:00:00+00:00, run_after=2025-01-28T06:00:00+00:00
[2025-01-28T00:12:51.745+0000] {processor.py:179} INFO - Processing /opt/airflow/dags/dag_d_pipeline_compass_reviews.py took 0.077 seconds
[2025-01-28T00:13:21.871+0000] {processor.py:157} INFO - Started process (PID=66) to work on /opt/airflow/dags/dag_d_pipeline_compass_reviews.py
[2025-01-28T00:13:21.872+0000] {processor.py:829} INFO - Processing file /opt/airflow/dags/dag_d_pipeline_compass_reviews.py for tasks to queue
[2025-01-28T00:13:21.874+0000] {logging_mixin.py:151} INFO - [2025-01-28T00:13:21.873+0000] {dagbag.py:536} INFO - Filling up the DagBag from /opt/airflow/dags/dag_d_pipeline_compass_reviews.py
[2025-01-28T00:13:21.883+0000] {logging_mixin.py:151} WARNING - /home/airflow/.local/lib/python3.8/site-packages/airflow/operators/python.py:177 RemovedInAirflow3Warning: The 'task_concurrency' parameter is deprecated. Please use 'max_active_tis_per_dag'.
[2025-01-28T00:13:21.889+0000] {processor.py:839} INFO - DAG(s) dict_keys(['dag_d_pipeline_compass_reviews']) retrieved from /opt/airflow/dags/dag_d_pipeline_compass_reviews.py
[2025-01-28T00:13:21.911+0000] {logging_mixin.py:151} INFO - [2025-01-28T00:13:21.911+0000] {dag.py:2941} INFO - Sync 1 DAGs
[2025-01-28T00:13:21.930+0000] {logging_mixin.py:151} INFO - [2025-01-28T00:13:21.930+0000] {dag.py:3722} INFO - Setting next_dagrun for dag_d_pipeline_compass_reviews to 2025-01-27T06:00:00+00:00, run_after=2025-01-28T06:00:00+00:00
[2025-01-28T00:13:21.946+0000] {processor.py:179} INFO - Processing /opt/airflow/dags/dag_d_pipeline_compass_reviews.py took 0.080 seconds
[2025-01-28T00:13:52.075+0000] {processor.py:157} INFO - Started process (PID=69) to work on /opt/airflow/dags/dag_d_pipeline_compass_reviews.py
[2025-01-28T00:13:52.081+0000] {processor.py:829} INFO - Processing file /opt/airflow/dags/dag_d_pipeline_compass_reviews.py for tasks to queue
[2025-01-28T00:13:52.084+0000] {logging_mixin.py:151} INFO - [2025-01-28T00:13:52.083+0000] {dagbag.py:536} INFO - Filling up the DagBag from /opt/airflow/dags/dag_d_pipeline_compass_reviews.py
[2025-01-28T00:13:52.098+0000] {logging_mixin.py:151} WARNING - /home/airflow/.local/lib/python3.8/site-packages/airflow/operators/python.py:177 RemovedInAirflow3Warning: The 'task_concurrency' parameter is deprecated. Please use 'max_active_tis_per_dag'.
[2025-01-28T00:13:52.106+0000] {processor.py:839} INFO - DAG(s) dict_keys(['dag_d_pipeline_compass_reviews']) retrieved from /opt/airflow/dags/dag_d_pipeline_compass_reviews.py
[2025-01-28T00:13:52.131+0000] {logging_mixin.py:151} INFO - [2025-01-28T00:13:52.131+0000] {dag.py:2941} INFO - Sync 1 DAGs
[2025-01-28T00:13:52.148+0000] {logging_mixin.py:151} INFO - [2025-01-28T00:13:52.148+0000] {dag.py:3722} INFO - Setting next_dagrun for dag_d_pipeline_compass_reviews to 2025-01-27T06:00:00+00:00, run_after=2025-01-28T06:00:00+00:00
[2025-01-28T00:13:52.163+0000] {processor.py:179} INFO - Processing /opt/airflow/dags/dag_d_pipeline_compass_reviews.py took 0.091 seconds
[2025-01-28T00:14:22.288+0000] {processor.py:157} INFO - Started process (PID=72) to work on /opt/airflow/dags/dag_d_pipeline_compass_reviews.py
[2025-01-28T00:14:22.290+0000] {processor.py:829} INFO - Processing file /opt/airflow/dags/dag_d_pipeline_compass_reviews.py for tasks to queue
[2025-01-28T00:14:22.292+0000] {logging_mixin.py:151} INFO - [2025-01-28T00:14:22.292+0000] {dagbag.py:536} INFO - Filling up the DagBag from /opt/airflow/dags/dag_d_pipeline_compass_reviews.py
[2025-01-28T00:14:22.309+0000] {logging_mixin.py:151} WARNING - /home/airflow/.local/lib/python3.8/site-packages/airflow/operators/python.py:177 RemovedInAirflow3Warning: The 'task_concurrency' parameter is deprecated. Please use 'max_active_tis_per_dag'.
[2025-01-28T00:14:22.315+0000] {processor.py:839} INFO - DAG(s) dict_keys(['dag_d_pipeline_compass_reviews']) retrieved from /opt/airflow/dags/dag_d_pipeline_compass_reviews.py
[2025-01-28T00:14:22.342+0000] {logging_mixin.py:151} INFO - [2025-01-28T00:14:22.342+0000] {dag.py:2941} INFO - Sync 1 DAGs
[2025-01-28T00:14:22.360+0000] {logging_mixin.py:151} INFO - [2025-01-28T00:14:22.360+0000] {dag.py:3722} INFO - Setting next_dagrun for dag_d_pipeline_compass_reviews to 2025-01-27T06:00:00+00:00, run_after=2025-01-28T06:00:00+00:00
[2025-01-28T00:14:22.375+0000] {processor.py:179} INFO - Processing /opt/airflow/dags/dag_d_pipeline_compass_reviews.py took 0.093 seconds
[2025-01-28T00:50:50.872+0000] {processor.py:157} INFO - Started process (PID=31) to work on /opt/airflow/dags/dag_d_pipeline_compass_reviews.py
[2025-01-28T00:50:50.876+0000] {processor.py:829} INFO - Processing file /opt/airflow/dags/dag_d_pipeline_compass_reviews.py for tasks to queue
[2025-01-28T00:50:50.878+0000] {logging_mixin.py:151} INFO - [2025-01-28T00:50:50.878+0000] {dagbag.py:536} INFO - Filling up the DagBag from /opt/airflow/dags/dag_d_pipeline_compass_reviews.py
[2025-01-28T00:50:50.892+0000] {logging_mixin.py:151} WARNING - /home/airflow/.local/lib/python3.8/site-packages/airflow/operators/python.py:177 RemovedInAirflow3Warning: The 'task_concurrency' parameter is deprecated. Please use 'max_active_tis_per_dag'.
[2025-01-28T00:50:50.903+0000] {processor.py:839} INFO - DAG(s) dict_keys(['dag_d_pipeline_compass_reviews']) retrieved from /opt/airflow/dags/dag_d_pipeline_compass_reviews.py
[2025-01-28T00:50:50.933+0000] {logging_mixin.py:151} INFO - [2025-01-28T00:50:50.933+0000] {dag.py:2941} INFO - Sync 1 DAGs
[2025-01-28T00:50:50.962+0000] {logging_mixin.py:151} INFO - [2025-01-28T00:50:50.961+0000] {dag.py:3722} INFO - Setting next_dagrun for dag_d_pipeline_compass_reviews to 2025-01-27T06:00:00+00:00, run_after=2025-01-28T06:00:00+00:00
[2025-01-28T00:50:50.993+0000] {processor.py:179} INFO - Processing /opt/airflow/dags/dag_d_pipeline_compass_reviews.py took 0.123 seconds
[2025-01-28T00:51:21.216+0000] {processor.py:157} INFO - Started process (PID=34) to work on /opt/airflow/dags/dag_d_pipeline_compass_reviews.py
[2025-01-28T00:51:21.219+0000] {processor.py:829} INFO - Processing file /opt/airflow/dags/dag_d_pipeline_compass_reviews.py for tasks to queue
[2025-01-28T00:51:21.221+0000] {logging_mixin.py:151} INFO - [2025-01-28T00:51:21.221+0000] {dagbag.py:536} INFO - Filling up the DagBag from /opt/airflow/dags/dag_d_pipeline_compass_reviews.py
[2025-01-28T00:51:21.241+0000] {logging_mixin.py:151} WARNING - /home/airflow/.local/lib/python3.8/site-packages/airflow/operators/python.py:177 RemovedInAirflow3Warning: The 'task_concurrency' parameter is deprecated. Please use 'max_active_tis_per_dag'.
[2025-01-28T00:51:21.251+0000] {processor.py:839} INFO - DAG(s) dict_keys(['dag_d_pipeline_compass_reviews']) retrieved from /opt/airflow/dags/dag_d_pipeline_compass_reviews.py
[2025-01-28T00:51:21.279+0000] {logging_mixin.py:151} INFO - [2025-01-28T00:51:21.279+0000] {dag.py:2941} INFO - Sync 1 DAGs
[2025-01-28T00:51:21.299+0000] {logging_mixin.py:151} INFO - [2025-01-28T00:51:21.299+0000] {dag.py:3722} INFO - Setting next_dagrun for dag_d_pipeline_compass_reviews to 2025-01-27T06:00:00+00:00, run_after=2025-01-28T06:00:00+00:00
[2025-01-28T00:51:21.323+0000] {processor.py:179} INFO - Processing /opt/airflow/dags/dag_d_pipeline_compass_reviews.py took 0.115 seconds
[2025-01-28T00:51:51.431+0000] {processor.py:157} INFO - Started process (PID=37) to work on /opt/airflow/dags/dag_d_pipeline_compass_reviews.py
[2025-01-28T00:51:51.432+0000] {processor.py:829} INFO - Processing file /opt/airflow/dags/dag_d_pipeline_compass_reviews.py for tasks to queue
[2025-01-28T00:51:51.433+0000] {logging_mixin.py:151} INFO - [2025-01-28T00:51:51.433+0000] {dagbag.py:536} INFO - Filling up the DagBag from /opt/airflow/dags/dag_d_pipeline_compass_reviews.py
[2025-01-28T00:51:51.443+0000] {logging_mixin.py:151} WARNING - /home/airflow/.local/lib/python3.8/site-packages/airflow/operators/python.py:177 RemovedInAirflow3Warning: The 'task_concurrency' parameter is deprecated. Please use 'max_active_tis_per_dag'.
[2025-01-28T00:51:51.449+0000] {processor.py:839} INFO - DAG(s) dict_keys(['dag_d_pipeline_compass_reviews']) retrieved from /opt/airflow/dags/dag_d_pipeline_compass_reviews.py
[2025-01-28T00:51:51.472+0000] {logging_mixin.py:151} INFO - [2025-01-28T00:51:51.472+0000] {dag.py:2941} INFO - Sync 1 DAGs
[2025-01-28T00:51:51.489+0000] {logging_mixin.py:151} INFO - [2025-01-28T00:51:51.489+0000] {dag.py:3722} INFO - Setting next_dagrun for dag_d_pipeline_compass_reviews to 2025-01-27T06:00:00+00:00, run_after=2025-01-28T06:00:00+00:00
[2025-01-28T00:51:51.509+0000] {processor.py:179} INFO - Processing /opt/airflow/dags/dag_d_pipeline_compass_reviews.py took 0.081 seconds
[2025-01-28T00:52:21.636+0000] {processor.py:157} INFO - Started process (PID=40) to work on /opt/airflow/dags/dag_d_pipeline_compass_reviews.py
[2025-01-28T00:52:21.637+0000] {processor.py:829} INFO - Processing file /opt/airflow/dags/dag_d_pipeline_compass_reviews.py for tasks to queue
[2025-01-28T00:52:21.638+0000] {logging_mixin.py:151} INFO - [2025-01-28T00:52:21.638+0000] {dagbag.py:536} INFO - Filling up the DagBag from /opt/airflow/dags/dag_d_pipeline_compass_reviews.py
[2025-01-28T00:52:21.649+0000] {logging_mixin.py:151} WARNING - /home/airflow/.local/lib/python3.8/site-packages/airflow/operators/python.py:177 RemovedInAirflow3Warning: The 'task_concurrency' parameter is deprecated. Please use 'max_active_tis_per_dag'.
[2025-01-28T00:52:21.657+0000] {processor.py:839} INFO - DAG(s) dict_keys(['dag_d_pipeline_compass_reviews']) retrieved from /opt/airflow/dags/dag_d_pipeline_compass_reviews.py
[2025-01-28T00:52:21.683+0000] {logging_mixin.py:151} INFO - [2025-01-28T00:52:21.683+0000] {dag.py:2941} INFO - Sync 1 DAGs
[2025-01-28T00:52:21.702+0000] {logging_mixin.py:151} INFO - [2025-01-28T00:52:21.702+0000] {dag.py:3722} INFO - Setting next_dagrun for dag_d_pipeline_compass_reviews to 2025-01-27T06:00:00+00:00, run_after=2025-01-28T06:00:00+00:00
[2025-01-28T00:52:21.716+0000] {processor.py:179} INFO - Processing /opt/airflow/dags/dag_d_pipeline_compass_reviews.py took 0.083 seconds
[2025-01-28T00:52:51.868+0000] {processor.py:157} INFO - Started process (PID=43) to work on /opt/airflow/dags/dag_d_pipeline_compass_reviews.py
[2025-01-28T00:52:51.869+0000] {processor.py:829} INFO - Processing file /opt/airflow/dags/dag_d_pipeline_compass_reviews.py for tasks to queue
[2025-01-28T00:52:51.871+0000] {logging_mixin.py:151} INFO - [2025-01-28T00:52:51.870+0000] {dagbag.py:536} INFO - Filling up the DagBag from /opt/airflow/dags/dag_d_pipeline_compass_reviews.py
[2025-01-28T00:52:51.883+0000] {logging_mixin.py:151} WARNING - /home/airflow/.local/lib/python3.8/site-packages/airflow/operators/python.py:177 RemovedInAirflow3Warning: The 'task_concurrency' parameter is deprecated. Please use 'max_active_tis_per_dag'.
[2025-01-28T00:52:51.889+0000] {processor.py:839} INFO - DAG(s) dict_keys(['dag_d_pipeline_compass_reviews']) retrieved from /opt/airflow/dags/dag_d_pipeline_compass_reviews.py
[2025-01-28T00:52:51.920+0000] {logging_mixin.py:151} INFO - [2025-01-28T00:52:51.920+0000] {dag.py:2941} INFO - Sync 1 DAGs
[2025-01-28T00:52:51.943+0000] {logging_mixin.py:151} INFO - [2025-01-28T00:52:51.943+0000] {dag.py:3722} INFO - Setting next_dagrun for dag_d_pipeline_compass_reviews to 2025-01-27T06:00:00+00:00, run_after=2025-01-28T06:00:00+00:00
[2025-01-28T00:52:51.958+0000] {processor.py:179} INFO - Processing /opt/airflow/dags/dag_d_pipeline_compass_reviews.py took 0.093 seconds
[2025-01-28T00:53:22.274+0000] {processor.py:157} INFO - Started process (PID=46) to work on /opt/airflow/dags/dag_d_pipeline_compass_reviews.py
[2025-01-28T00:53:22.297+0000] {processor.py:829} INFO - Processing file /opt/airflow/dags/dag_d_pipeline_compass_reviews.py for tasks to queue
[2025-01-28T00:53:22.299+0000] {logging_mixin.py:151} INFO - [2025-01-28T00:53:22.299+0000] {dagbag.py:536} INFO - Filling up the DagBag from /opt/airflow/dags/dag_d_pipeline_compass_reviews.py
[2025-01-28T00:53:22.309+0000] {logging_mixin.py:151} WARNING - /home/airflow/.local/lib/python3.8/site-packages/airflow/operators/python.py:177 RemovedInAirflow3Warning: The 'task_concurrency' parameter is deprecated. Please use 'max_active_tis_per_dag'.
[2025-01-28T00:53:22.315+0000] {processor.py:839} INFO - DAG(s) dict_keys(['dag_d_pipeline_compass_reviews']) retrieved from /opt/airflow/dags/dag_d_pipeline_compass_reviews.py
[2025-01-28T00:53:22.341+0000] {logging_mixin.py:151} INFO - [2025-01-28T00:53:22.341+0000] {dag.py:2941} INFO - Sync 1 DAGs
[2025-01-28T00:53:22.359+0000] {logging_mixin.py:151} INFO - [2025-01-28T00:53:22.359+0000] {dag.py:3722} INFO - Setting next_dagrun for dag_d_pipeline_compass_reviews to 2025-01-27T06:00:00+00:00, run_after=2025-01-28T06:00:00+00:00
[2025-01-28T00:53:22.375+0000] {processor.py:179} INFO - Processing /opt/airflow/dags/dag_d_pipeline_compass_reviews.py took 0.103 seconds
[2025-01-28T00:53:52.462+0000] {processor.py:157} INFO - Started process (PID=49) to work on /opt/airflow/dags/dag_d_pipeline_compass_reviews.py
[2025-01-28T00:53:52.463+0000] {processor.py:829} INFO - Processing file /opt/airflow/dags/dag_d_pipeline_compass_reviews.py for tasks to queue
[2025-01-28T00:53:52.464+0000] {logging_mixin.py:151} INFO - [2025-01-28T00:53:52.464+0000] {dagbag.py:536} INFO - Filling up the DagBag from /opt/airflow/dags/dag_d_pipeline_compass_reviews.py
[2025-01-28T00:53:52.474+0000] {logging_mixin.py:151} WARNING - /home/airflow/.local/lib/python3.8/site-packages/airflow/operators/python.py:177 RemovedInAirflow3Warning: The 'task_concurrency' parameter is deprecated. Please use 'max_active_tis_per_dag'.
[2025-01-28T00:53:52.479+0000] {processor.py:839} INFO - DAG(s) dict_keys(['dag_d_pipeline_compass_reviews']) retrieved from /opt/airflow/dags/dag_d_pipeline_compass_reviews.py
[2025-01-28T00:53:52.505+0000] {logging_mixin.py:151} INFO - [2025-01-28T00:53:52.505+0000] {dag.py:2941} INFO - Sync 1 DAGs
[2025-01-28T00:53:52.521+0000] {logging_mixin.py:151} INFO - [2025-01-28T00:53:52.521+0000] {dag.py:3722} INFO - Setting next_dagrun for dag_d_pipeline_compass_reviews to 2025-01-27T06:00:00+00:00, run_after=2025-01-28T06:00:00+00:00
[2025-01-28T00:53:52.536+0000] {processor.py:179} INFO - Processing /opt/airflow/dags/dag_d_pipeline_compass_reviews.py took 0.076 seconds
[2025-01-28T00:54:22.657+0000] {processor.py:157} INFO - Started process (PID=52) to work on /opt/airflow/dags/dag_d_pipeline_compass_reviews.py
[2025-01-28T00:54:22.658+0000] {processor.py:829} INFO - Processing file /opt/airflow/dags/dag_d_pipeline_compass_reviews.py for tasks to queue
[2025-01-28T00:54:22.659+0000] {logging_mixin.py:151} INFO - [2025-01-28T00:54:22.659+0000] {dagbag.py:536} INFO - Filling up the DagBag from /opt/airflow/dags/dag_d_pipeline_compass_reviews.py
[2025-01-28T00:54:22.670+0000] {logging_mixin.py:151} WARNING - /home/airflow/.local/lib/python3.8/site-packages/airflow/operators/python.py:177 RemovedInAirflow3Warning: The 'task_concurrency' parameter is deprecated. Please use 'max_active_tis_per_dag'.
[2025-01-28T00:54:22.675+0000] {processor.py:839} INFO - DAG(s) dict_keys(['dag_d_pipeline_compass_reviews']) retrieved from /opt/airflow/dags/dag_d_pipeline_compass_reviews.py
[2025-01-28T00:54:22.697+0000] {logging_mixin.py:151} INFO - [2025-01-28T00:54:22.697+0000] {dag.py:2941} INFO - Sync 1 DAGs
[2025-01-28T00:54:22.714+0000] {logging_mixin.py:151} INFO - [2025-01-28T00:54:22.714+0000] {dag.py:3722} INFO - Setting next_dagrun for dag_d_pipeline_compass_reviews to 2025-01-27T06:00:00+00:00, run_after=2025-01-28T06:00:00+00:00
[2025-01-28T00:54:22.728+0000] {processor.py:179} INFO - Processing /opt/airflow/dags/dag_d_pipeline_compass_reviews.py took 0.074 seconds
