[2025-02-02T04:01:05.827+0000] {taskinstance.py:1159} INFO - Dependencies all met for dep_context=non-requeueable deps ti=<TaskInstance: dag_d_pipeline_compass_reviews.group_jobs_quality_silver.S_QUALITY_PIPELINE_APP_REVIEWS_SANTANDER manual__2025-02-02T03:45:16.018624+00:00 [queued]>
[2025-02-02T04:01:05.836+0000] {taskinstance.py:1159} INFO - Dependencies all met for dep_context=requeueable deps ti=<TaskInstance: dag_d_pipeline_compass_reviews.group_jobs_quality_silver.S_QUALITY_PIPELINE_APP_REVIEWS_SANTANDER manual__2025-02-02T03:45:16.018624+00:00 [queued]>
[2025-02-02T04:01:05.836+0000] {taskinstance.py:1361} INFO - Starting attempt 1 of 2
[2025-02-02T04:01:05.846+0000] {taskinstance.py:1382} INFO - Executing <Task(PythonOperator): group_jobs_quality_silver.S_QUALITY_PIPELINE_APP_REVIEWS_SANTANDER> on 2025-02-02 03:45:16.018624+00:00
[2025-02-02T04:01:05.849+0000] {standard_task_runner.py:57} INFO - Started process 387 to run task
[2025-02-02T04:01:05.852+0000] {standard_task_runner.py:84} INFO - Running: ['***', 'tasks', 'run', 'dag_d_pipeline_compass_reviews', 'group_jobs_quality_silver.S_QUALITY_PIPELINE_APP_REVIEWS_SANTANDER', 'manual__2025-02-02T03:45:16.018624+00:00', '--job-id', '606', '--raw', '--subdir', 'DAGS_FOLDER/dag_d_pipeline_compass_reviews.py', '--cfg-path', '/tmp/tmp3dv5yvm5']
[2025-02-02T04:01:05.852+0000] {standard_task_runner.py:85} INFO - Job 606: Subtask group_jobs_quality_silver.S_QUALITY_PIPELINE_APP_REVIEWS_SANTANDER
[2025-02-02T04:01:05.888+0000] {task_command.py:416} INFO - Running <TaskInstance: dag_d_pipeline_compass_reviews.group_jobs_quality_silver.S_QUALITY_PIPELINE_APP_REVIEWS_SANTANDER manual__2025-02-02T03:45:16.018624+00:00 [running]> on host 4a4dd3fdf7fb
[2025-02-02T04:01:05.952+0000] {taskinstance.py:1662} INFO - Exporting env vars: AIRFLOW_CTX_DAG_EMAIL='gacarvalho.contato@gmail.com' AIRFLOW_CTX_DAG_OWNER='gacarvalho' AIRFLOW_CTX_DAG_ID='dag_d_pipeline_compass_reviews' AIRFLOW_CTX_TASK_ID='group_jobs_quality_silver.S_QUALITY_PIPELINE_APP_REVIEWS_SANTANDER' AIRFLOW_CTX_EXECUTION_DATE='2025-02-02T03:45:16.018624+00:00' AIRFLOW_CTX_TRY_NUMBER='1' AIRFLOW_CTX_DAG_RUN_ID='manual__2025-02-02T03:45:16.018624+00:00'
[2025-02-02T04:01:29.603+0000] {logging_mixin.py:151} INFO - Erro ao executar Docker Run: Command '['docker', 'run', '--rm', '--network', 'hadoop_network', '-e', 'CONFIG_ENV=prod', '-e', 'PARAM1=silver', '-v', '/env/.env:/app/.env', '-v', '/opt/***/data:/app/data', 'iamgacarvalho/dmc-quality-pipeline-compass:1.0.0']' returned non-zero exit status 1.
[2025-02-02T04:01:29.603+0000] {taskinstance.py:1937} ERROR - Task failed with exception
Traceback (most recent call last):
  File "/home/airflow/.local/lib/python3.8/site-packages/airflow/operators/python.py", line 192, in execute
    return_value = self.execute_callable()
  File "/home/airflow/.local/lib/python3.8/site-packages/airflow/operators/python.py", line 209, in execute_callable
    return self.python_callable(*self.op_args, **self.op_kwargs)
  File "/opt/airflow/dags/dag_d_pipeline_compass_reviews.py", line 41, in run_docker_run
    subprocess.run(command, check=True, env=os.environ.copy())
  File "/usr/local/lib/python3.8/subprocess.py", line 516, in run
    raise CalledProcessError(retcode, process.args,
subprocess.CalledProcessError: Command '['docker', 'run', '--rm', '--network', 'hadoop_network', '-e', 'CONFIG_ENV=prod', '-e', 'PARAM1=silver', '-v', '/env/.env:/app/.env', '-v', '/opt/airflow/data:/app/data', 'iamgacarvalho/dmc-quality-pipeline-compass:1.0.0']' returned non-zero exit status 1.
[2025-02-02T04:01:29.611+0000] {taskinstance.py:1400} INFO - Marking task as UP_FOR_RETRY. dag_id=dag_d_pipeline_compass_reviews, task_id=group_jobs_quality_silver.S_QUALITY_PIPELINE_APP_REVIEWS_SANTANDER, execution_date=20250202T034516, start_date=20250202T040105, end_date=20250202T040129
[2025-02-02T04:01:29.623+0000] {warnings.py:109} WARNING - /home/***/.local/lib/python3.8/site-packages/***/utils/email.py:154: RemovedInAirflow3Warning: Fetching SMTP credentials from configuration variables will be deprecated in a future release. Please set credentials using a connection instead.
  send_mime_email(e_from=mail_from, e_to=recipients, mime_msg=msg, conn_id=conn_id, dryrun=dryrun)

[2025-02-02T04:01:29.624+0000] {configuration.py:1068} WARNING - section/key [smtp/smtp_user] not found in config
[2025-02-02T04:01:29.624+0000] {email.py:270} INFO - Email alerting: attempt 1
[2025-02-02T04:01:29.629+0000] {configuration.py:1068} WARNING - section/key [smtp/smtp_user] not found in config
[2025-02-02T04:01:29.629+0000] {email.py:270} INFO - Email alerting: attempt 1
[2025-02-02T04:01:29.630+0000] {taskinstance.py:2007} ERROR - Failed to send email to: ['gacarvalho.contato@gmail.com']
Traceback (most recent call last):
  File "/home/airflow/.local/lib/python3.8/site-packages/airflow/models/taskinstance.py", line 1518, in _run_raw_task
    self._execute_task_with_callbacks(context, test_mode, session=session)
  File "/home/airflow/.local/lib/python3.8/site-packages/airflow/models/taskinstance.py", line 1681, in _execute_task_with_callbacks
    result = self._execute_task(context, task_orig)
  File "/home/airflow/.local/lib/python3.8/site-packages/airflow/models/taskinstance.py", line 1744, in _execute_task
    result = execute_callable(context=context, **execute_callable_kwargs)
  File "/home/airflow/.local/lib/python3.8/site-packages/airflow/operators/python.py", line 192, in execute
    return_value = self.execute_callable()
  File "/home/airflow/.local/lib/python3.8/site-packages/airflow/operators/python.py", line 209, in execute_callable
    return self.python_callable(*self.op_args, **self.op_kwargs)
  File "/opt/airflow/dags/dag_d_pipeline_compass_reviews.py", line 41, in run_docker_run
    subprocess.run(command, check=True, env=os.environ.copy())
  File "/usr/local/lib/python3.8/subprocess.py", line 516, in run
    raise CalledProcessError(retcode, process.args,
subprocess.CalledProcessError: Command '['docker', 'run', '--rm', '--network', 'hadoop_network', '-e', 'CONFIG_ENV=prod', '-e', 'PARAM1=silver', '-v', '/env/.env:/app/.env', '-v', '/opt/airflow/data:/app/data', 'iamgacarvalho/dmc-quality-pipeline-compass:1.0.0']' returned non-zero exit status 1.

During handling of the above exception, another exception occurred:

Traceback (most recent call last):
  File "/home/airflow/.local/lib/python3.8/site-packages/airflow/models/taskinstance.py", line 2420, in email_alert
    send_email(task.email, subject, html_content)
  File "/home/airflow/.local/lib/python3.8/site-packages/airflow/utils/email.py", line 80, in send_email
    return backend(
  File "/home/airflow/.local/lib/python3.8/site-packages/airflow/utils/email.py", line 154, in send_email_smtp
    send_mime_email(e_from=mail_from, e_to=recipients, mime_msg=msg, conn_id=conn_id, dryrun=dryrun)
  File "/home/airflow/.local/lib/python3.8/site-packages/airflow/utils/email.py", line 272, in send_mime_email
    smtp_conn = _get_smtp_connection(smtp_host, smtp_port, smtp_timeout, smtp_ssl)
  File "/home/airflow/.local/lib/python3.8/site-packages/airflow/utils/email.py", line 316, in _get_smtp_connection
    return smtplib.SMTP(host=host, port=port, timeout=timeout)
  File "/usr/local/lib/python3.8/smtplib.py", line 255, in __init__
    (code, msg) = self.connect(host, port)
  File "/usr/local/lib/python3.8/smtplib.py", line 339, in connect
    self.sock = self._get_socket(host, port, self.timeout)
  File "/usr/local/lib/python3.8/smtplib.py", line 310, in _get_socket
    return socket.create_connection((host, port), timeout,
  File "/usr/local/lib/python3.8/socket.py", line 808, in create_connection
    raise err
  File "/usr/local/lib/python3.8/socket.py", line 796, in create_connection
    sock.connect(sa)
ConnectionRefusedError: [Errno 111] Connection refused

During handling of the above exception, another exception occurred:

Traceback (most recent call last):
  File "/home/airflow/.local/lib/python3.8/site-packages/airflow/models/taskinstance.py", line 2005, in handle_failure
    self.email_alert(error, task)
  File "/home/airflow/.local/lib/python3.8/site-packages/airflow/models/taskinstance.py", line 2422, in email_alert
    send_email(task.email, subject, html_content_err)
  File "/home/airflow/.local/lib/python3.8/site-packages/airflow/utils/email.py", line 80, in send_email
    return backend(
  File "/home/airflow/.local/lib/python3.8/site-packages/airflow/utils/email.py", line 154, in send_email_smtp
    send_mime_email(e_from=mail_from, e_to=recipients, mime_msg=msg, conn_id=conn_id, dryrun=dryrun)
  File "/home/airflow/.local/lib/python3.8/site-packages/airflow/utils/email.py", line 272, in send_mime_email
    smtp_conn = _get_smtp_connection(smtp_host, smtp_port, smtp_timeout, smtp_ssl)
  File "/home/airflow/.local/lib/python3.8/site-packages/airflow/utils/email.py", line 316, in _get_smtp_connection
    return smtplib.SMTP(host=host, port=port, timeout=timeout)
  File "/usr/local/lib/python3.8/smtplib.py", line 255, in __init__
    (code, msg) = self.connect(host, port)
  File "/usr/local/lib/python3.8/smtplib.py", line 339, in connect
    self.sock = self._get_socket(host, port, self.timeout)
  File "/usr/local/lib/python3.8/smtplib.py", line 310, in _get_socket
    return socket.create_connection((host, port), timeout,
  File "/usr/local/lib/python3.8/socket.py", line 808, in create_connection
    raise err
  File "/usr/local/lib/python3.8/socket.py", line 796, in create_connection
    sock.connect(sa)
ConnectionRefusedError: [Errno 111] Connection refused
[2025-02-02T04:01:29.644+0000] {standard_task_runner.py:104} ERROR - Failed to execute job 606 for task group_jobs_quality_silver.S_QUALITY_PIPELINE_APP_REVIEWS_SANTANDER (Command '['docker', 'run', '--rm', '--network', 'hadoop_network', '-e', 'CONFIG_ENV=prod', '-e', 'PARAM1=silver', '-v', '/env/.env:/app/.env', '-v', '/opt/airflow/data:/app/data', 'iamgacarvalho/dmc-quality-pipeline-compass:1.0.0']' returned non-zero exit status 1.; 387)
[2025-02-02T04:01:29.648+0000] {local_task_job_runner.py:228} INFO - Task exited with return code 1
[2025-02-02T04:01:29.660+0000] {taskinstance.py:2778} INFO - 0 downstream tasks scheduled from follow-on schedule check
